Workbook

Sheet PROJETO PERFURAÇÃO
A1: Data | B1: ID | C1: Geometry | D1: Zone | E1: Phase | F1: Bench | G1: Domain | H1: Project | I1: Lithology | J1: Mat Blast | K1: GF | L1: Model | M1: GR | N1: GA | O1: RMR | P1: Type | Q1: Explosivo | R1: Reforcador | S1: Iniciador Primario | T1: Iniciador Backup | U1: Inicio | V1: Fim | W1: Operador | X1: Frota | Y1: Equipamento | Z1: Descricao | AA1: Observacao | AB1: Diameter | AC1: X Collar | AD1: Y Collar | AE1: Z Collar | AF1: X Toe | AG1: Y Toe | AH1: Z Toe | AI1: Depth | AJ1: Sub Drill | AK1: Spacing | AL1: Burden | AM1: Azimuth | AN1: Dip | AO1: Tonnes | AP1: Density | AQ1: Cu (%) | AR1: Au (%) | AS1: Ni (%) | AT1: Fe (%) | AU1: Mg (%) | AV1: S (%) | AW1: Cu:S (%) | AX1: Cu SC_Cu T (%) | AY1: Tampao | AZ1: Carga | BA1: DIFFX | BB1: DIFFXY | BC1: DIFFZ | BD1: DIFFY
A2: 46304 | B2: 1 | C2: LIB065 | D2: NE | E2: 2 | F2: 185 | G2: 1 | H2: PP0651026 | I2: Gneiss | J2: ORE_MG_TP1_D1 | K2: F3 | L2: T:\MINA\Drill and blast\Deswik\MB_CP_MVV_final.gmdlb | M2: R5 | O2: II | P2: Pre-Splitting | X2: Sandvik DP1500i | Z2: Planned | AB2: 5 | AC2: 748798.93 | AD2: 8930540.5 | AE2: 194.62 | AF2: 748799.44 | AG2: 8930537.9 | AH2: 185 | AI2: 9.98 | AJ2: 0 | AK2: 1.5 | AL2: 0.8 | AM2: 169.06 | AN2: 15.56 | AO2: 0 | AP2: 3.28 | AQ2: 0.4 | AR2: 0.06 | AS2: 0.06 | AT2: 17.33 | AU2: 5.53 | AV2: 0.27 | AW2: 1.44 | AX2: 0 | AY2: 0 | AZ2: 0 | BA2: 0 | BB2: 0 | BC2: 0 | BD2: 0
A3: 46304 | B3: 2 | C3: LIB065 | D3: NE | E3: 2 | F3: 185 | G3: 1 | H3: PP0651026 | I3: Gneiss | J3: ORE_MG_TP1_D1 | K3: F3 | L3: T:\MINA\Drill and blast\Deswik\MB_CP_MVV_final.gmdlb | M3: R5 | O3: II | P3: Pre-Splitting | X3: Sandvik DP1500i | Z3: Planned | AB3: 5 | AC3: 748797.46 | AD3: 8930540.3 | AE3: 194.56 | AF3: 748797.96 | AG3: 8930537.6 | AH3: 185 | AI3: 9.93 | AJ3: 0 | AK3: 1.5 | AL3: 0.8 | AM3: 169.06 | AN3: 15.65 | AO3: 0 | AP3: 3.28 | AQ3: 0.41 | AR3: 0.06 | AS3: 0.06 | AT3: 17.18 | AU3: 5.55 | AV3: 0.26 | AW3: 1.37 | AX3: 0 | AY3: 0 | AZ3: 0 | BA3: 0 | BB3: 0 | BC3: 0 | BD3: 0
A4: 46304 | B4: 3 | C4: LIB065 | D4: NE | E4: 2 | F4: 185 | G4: 1 | H4: PP0651026 | I4: Gneiss | J4: ORE_MG_TP1_D1 | K4: F3 | L4: T:\MINA\Drill and blast\Deswik\MB_CP_MVV_final.gmdlb | M4: R5 | O4: II | P4: Pre-Splitting | X4: Sandvik DP1500i | Z4: Planned | AB4: 5 | AC4: 748795.98 | AD4: 8930540 | AE4: 194.56 | AF4: 748796.49 | AG4: 8930537.3 | AH4: 185 | AI4: 9.92 | AJ4: 0 | AK4: 1.5 | AL4: 0.8 | AM4: 169.06 | AN4: 15.66 | AO4: 0 | AP4: 3.28 | AQ4: 0.41 | AR4: 0.06 | AS4: 0.06 | AT4: 16.93 | AU4: 5.58 | AV4: 0.25 | AW4: 1.27 | AX4: 0 | AY4: 0 | AZ4: 0 | BA4: 0 | BB4: 0 | BC4: 0 | BD4: 0
A5: 46304 | B5: 4 | C5: LIB065 | D5: NE | E5: 2 | F5: 185 | G5: 1 | H5: PP0651026 | I5: Gneiss | J5: ORE_MG_TP1_D1 | K5: F3 | L5: T:\MINA\Drill and blast\Deswik\MB_CP_MVV_final.gmdlb | M5: R5 | O5: II | P5: Pre-Splitting | X5: Sandvik DP1500i | Z5: Planned | AB5: 5 | AC5: 748794.51 | AD5: 8930539.7 | AE5: 194.6 | AF5: 748795.02 | AG5: 8930537.1 | AH5: 185 | AI5: 9.97 | AJ5: 0 | AK5: 1.5 | AL5: 0.8 | AM5: 169.06 | AN5: 15.6 | AO5: 0 | AP5: 3.29 | AQ5: 0.42 | AR5: 0.06 | AS5: 0.06 | AT5: 16.59 | AU5: 5.62 | AV5: 0.22 | AW5: 1.13 | AX5: 0 | AY5: 0 | AZ5: 0 | BA5: 0 | BB5: 0 | BC5: 0 | BD5: 0
A6: 46304 | B6: 5 | C6: LIB065 | D6: NE | E6: 2 | F6: 185 | G6: 1 | H6: PP0651026 | I6: Gneiss | J6: ORE_MG_TP1_D1 | K6: F3 | L6: T:\MINA\Drill and blast\Deswik\MB_CP_MVV_final.gmdlb | M6: R5 | O6: II | P6: Pre-Splitting | X6: Sandvik DP1500i | Z6: Planned | AB6: 5 | AC6: 748793.04 | AD6: 8930539.4 | AE6: 194.58 | AF6: 748793.55 | AG6: 8930536.8 | AH6: 185 | AI6: 9.95 | AJ6: 0 | AK6: 1.5 | AL6: 0.8 | AM6: 169.06 | AN6: 15.63 | AO6: 0 | AP6: 3.29 | AQ6: 0.42 | AR6: 0.06 | AS6: 0.06 | AT6: 16.59 | AU6: 5.62 | AV6: 0.22 | AW6: 1.13 | AX6: 0 | AY6: 0 | AZ6: 0 | BA6: 0 | BB6: 0 | BC6: 0 | BD6: 0
A7: 46304 | B7: 6 | C7: LIB065 | D7: NE | E7: 2 | F7: 185 | G7: 1 | H7: PP0651026 | I7: Gneiss | J7: ORE_MG_TP1_D1 | K7: F3 | L7: T:\MINA\Drill and blast\Deswik\MB_CP_MVV_final.gmdlb | M7: R5 | O7: II | P7: Pre-Splitting | X7: Sandvik DP1500i | Z7: Planned | AB7: 5 | AC7: 748791.57 | AD7: 8930539.1 | AE7: 194.57 | AF7: 748792.07 | AG7: 8930536.5 | AH7: 185 | AI7: 9.94 | AJ7: 0 | AK7: 1.5 | AL7: 0.8 | AM7: 169.06 | AN7: 15.64 | AO7: 0 | AP7: 3.29 | AQ7: 0.42 | AR7: 0.06 | AS7: 0.06 | AT7: 16.59 | AU7: 5.62 | AV7: 0.22 | AW7: 1.13 | AX7: 0 | AY7: 0 | AZ7: 0 | BA7: 0 | BB7: 0 | BC7: 0 | BD7: 0
A8: 46304 | B8: 7 | C8: LIB065 | D8: NE | E8: 2 | F8: 185 | G8: 1 | H8: PP0651026 | I8: Gneiss | J8: ORE_MG_TP1_D1 | K8: F3 | L8: T:\MINA\Drill and blast\Deswik\MB_CP_MVV_final.gmdlb | M8: R5 | O8: II | P8: Pre-Splitting | X8: Sandvik DP1500i | Z8: Planned | AB8: 5 | AC8: 748790.09 | AD8: 8930538.8 | AE8: 194.54 | AF8: 748790.62 | AG8: 8930536.2 | AH8: 185 | AI8: 9.91 | AJ8: 0 | AK8: 1.5 | AL8: 0.8 | AM8: 168.64 | AN8: 15.73 | AO8: 0 | AP8: 3.3 | AQ8: 0.42 | AR8: 0.06 | AS8: 0.06 | AT8: 16.24 | AU8: 5.66 | AV8: 0.2 | AW8: 0.99 | AX8: 0 | AY8: 0 | AZ8: 0 | BA8: 0 | BB8: 0 | BC8: 0 | BD8: 0
A9: 46304 | B9: 8 | C9: LIB065 | D9: NE | E9: 2 | F9: 185 | G9: 1 | H9: PP0651026 | I9: Gabbro | J9: ORE_MG_TP1_D1 | K9: F3 | L9: T:\MINA\Drill and blast\Deswik\MB_CP_MVV_final.gmdlb | M9: R5 | O9: II | P9: Pre-Splitting | X9: Sandvik DP1500i | Z9: Planned | AB9: 5 | AC9: 748788.63 | AD9: 8930538.5 | AE9: 194.56 | AF9: 748789.24 | AG9: 8930535.9 | AH9: 185 | AI9: 9.92 | AJ9: 0 | AK9: 1.5 | AL9: 0.8 | AM9: 166.99 | AN9: 15.65 | AO9: 0 | AP9: 3.29 | AQ9: 0.42 | AR9: 0.06 | AS9: 0.06 | AT9: 15.78 | AU9: 5.76 | AV9: 0.17 | AW9: 0.88 | AX9: 0 | AY9: 0 | AZ9: 0 | BA9: 0 | BB9: 0 | BC9: 0 | BD9: 0
A10: 46304 | B10: 9 | C10: LIB065 | D10: NE | E10: 2 | F10: 185 | G10: 1 | H10: PP0651026 | I10: Gabbro | J10: ORE_MG_TP1_D1 | K10: F3 | L10: T:\MINA\Drill and blast\Deswik\MB_CP_MVV_final.gmdlb | M10: R5 | O10: II | P10: Pre-Splitting | X10: Sandvik DP1500i | Z10: Planned | AB10: 5 | AC10: 748787.17 | AD10: 8930538.1 | AE10: 194.69 | AF10: 748787.77 | AG10: 8930535.5 | AH10: 185 | AI10: 10.05 | AJ10: 0 | AK10: 1.5 | AL10: 0.8 | AM10: 166.99 | AN10: 15.4 | AO10: 0 | AP10: 3.28 | AQ10: 0.42 | AR10: 0.06 | AS10: 0.06 | AT10: 15.25 | AU10: 5.87 | AV10: 0.14 | AW10: 0.76 | AX10: 0 | AY10: 0 | AZ10: 0 | BA10: 0 | BB10: 0 | BC10: 0 | BD10: 0
A11: 46304 | B11: 10 | C11: LIB065 | D11: NE | E11: 2 | F11: 185 | G11: 1 | H11: PP0651026 | I11: Gabbro | J11: ORE_MG_TP1_D1 | K11: F3 | L11: T:\MINA\Drill and blast\Deswik\MB_CP_MVV_final.gmdlb | M11: R5 | O11: II | P11: Pre-Splitting | X11: Sandvik DP1500i | Z11: Planned | AB11: 5 | AC11: 748785.71 | AD11: 8930537.8 | AE11: 194.94 | AF11: 748786.31 | AG11: 8930535.2 | AH11: 185 | AI11: 10.3 | AJ11: 0 | AK11: 1.5 | AL11: 0.8 | AM11: 166.99 | AN11: 15.06 | AO11: 0 | AP11: 3.27 | AQ11: 0.41 | AR11: 0.06 | AS11: 0.05 | AT11: 14.76 | AU11: 5.92 | AV11: 0.11 | AW11: 0.62 | AX11: 0 | AY11: 0 | AZ11: 0 | BA11: 0 | BB11: 0 | BC11: 0 | BD11: 0
A12: 46304 | B12: 11 | C12: LIB065 | D12: NE | E12: 2 | F12: 185 | G12: 1 | H12: PP0651026 | I12: Gabbro | J12: ORE_MG_TP1_D1 | K12: F3 | L12: T:\MINA\Drill and blast\Deswik\MB_CP_MVV_final.gmdlb | M12: R5 | O12: II | P12: Pre-Splitting | X12: Sandvik DP1500i | Z12: Planned | AB12: 5 | AC12: 748784.25 | AD12: 8930537.5 | AE12: 195.16 | AF12: 748784.85 | AG12: 8930534.9 | AH12: 185 | AI12: 10.5 | AJ12: 0 | AK12: 1.5 | AL12: 0.8 | AM12: 166.99 | AN12: 14.77 | AO12: 0 | AP12: 3.27 | AQ12: 0.41 | AR12: 0.06 | AS12: 0.05 | AT12: 14.39 | AU12: 5.92 | AV12: 0.09 | AW12: 0.5 | AX12: 0 | AY12: 0 | AZ12: 0 | BA12: 0 | BB12: 0 | BC12: 0 | BD12: 0
A13: 46304 | B13: 12 | C13: LIB065 | D13: NE | E13: 2 | F13: 185 | G13: 0 | H13: PP0651026 | I13: Gabbro | J13: ORE_MG_TP1_D1 | K13: F3 | L13: T:\MINA\Drill and blast\Deswik\MB_CP_MVV_final.gmdlb | M13: R5 | O13: II | P13: Pre-Splitting | X13: Sandvik DP1500i | Z13: Planned | AB13: 5 | AC13: 748782.79 | AD13: 8930537.1 | AE13: 195.15 | AF13: 748783.39 | AG13: 8930534.5 | AH13: 185 | AI13: 10.5 | AJ13: 0 | AK13: 1.5 | AL13: 0.8 | AM13: 166.99 | AN13: 14.78 | AO13: 0 | AP13: 3.27 | AQ13: 0.41 | AR13: 0.06 | AS13: 0.05 | AT13: 14.02 | AU13: 5.92 | AV13: 0.07 | AW13: 0.38 | AX13: 0 | AY13: 0 | AZ13: 0 | BA13: 0 | BB13: 0 | BC13: 0 | BD13: 0
... A103: 46304 | B103: 102 | C103: LIB065 | D103: NW | E103: 2 | F103: 185 | G103: 0 | H103: PP0651026 | I103: Gneiss | J103: WST | K103: NA | L103: T:\MINA\Drill and blast\Deswik\MB_CP_MVV_final.gmdlb | M103: R1 | O103: II | P103: Pre-Splitting | X103: Sandvik DP1500i | Z103: Planned | AB103: 5 | AC103: 748690.4 | AD103: 8930446.9 | AE103: 189.66 | AF103: 748691.55 | AG103: 8930446.2 | AH103: 185 | AI103: 4.85 | AJ103: 0 | AK103: 1.5 | AL103: 0.8 | AM103: 120.74 | AN103: 16.08 | AO103: 0 | AP103: 2.81 | AQ103: 0 | AR103: 0 | AS103: 0 | AT103: 0 | AU103: 0 | AV103: 0 | AW103: 0 | AX103: 0 | AY103: 0 | AZ103: 0 | BA103: 0 | BB103: 0 | BC103: 0 | BD103: 0
A104: 46304 | B104: 103 | C104: LIB065 | D104: NW | E104: 0 | F104: 185 | G104: 0 | H104: PP0651026 | J104: WST | L104: T:\MINA\Drill and blast\Deswik\MB_CP_MVV_final.gmdlb | O104: II | P104: Pre-Splitting | X104: Sandvik DP1500i | Z104: Planned | AB104: 5 | AC104: 748689.92 | AD104: 8930445.5 | AE104: 189.64 | AF104: 748691.19 | AG104: 8930445.1 | AH104: 185 | AI104: 4.83 | AJ104: 0 | AK104: 1.5 | AL104: 0.8 | AM104: 108.64 | AN104: 16.16 | AO104: 0 | AP104: 2.81 | AQ104: 0 | AR104: 0 | AS104: 0 | AT104: 0 | AU104: 0 | AV104: 0 | AW104: 0 | AX104: 0 | AY104: 0 | AZ104: 0 | BA104: 0 | BB104: 0 | BC104: 0 | BD104: 0
A105: 46304 | B105: 104 | C105: LIB065 | D105: NW | E105: 0 | F105: 185 | G105: 0 | H105: PP0651026 | J105: WST | L105: T:\MINA\Drill and blast\Deswik\MB_CP_MVV_final.gmdlb | O105: II | P105: Pre-Splitting | X105: Sandvik DP1500i | Z105: Planned | AB105: 5 | AC105: 748689.5 | AD105: 8930444 | AE105: 189.59 | AF105: 748690.79 | AG105: 8930443.7 | AH105: 185 | AI105: 4.78 | AJ105: 0 | AK105: 1.5 | AL105: 0.8 | AM105: 106.29 | AN105: 16.32 | AO105: 0 | AP105: 2.82 | AQ105: 0 | AR105: 0 | AS105: 0 | AT105: 0 | AU105: 0 | AV105: 0 | AW105: 0 | AX105: 0 | AY105: 0 | AZ105: 0 | BA105: 0 | BB105: 0 | BC105: 0 | BD105: 0
A106: 46304 | B106: 105 | C106: LIB065 | D106: NW | E106: 0 | F106: 185 | G106: 0 | H106: PP0651026 | J106: WST | L106: T:\MINA\Drill and blast\Deswik\MB_CP_MVV_final.gmdlb | O106: II | P106: Pre-Splitting | X106: Sandvik DP1500i | Z106: Planned | AB106: 5 | AC106: 748689.08 | AD106: 8930442.6 | AE106: 189.57 | AF106: 748690.37 | AG106: 8930442.2 | AH106: 185 | AI106: 4.77 | AJ106: 0 | AK106: 1.5 | AL106: 0.8 | AM106: 106.29 | AN106: 16.4 | AO106: 0 | AP106: 2.8 | AQ106: 0 | AR106: 0 | AS106: 0 | AT106: 0 | AU106: 0 | AV106: 0 | AW106: 0 | AX106: 0 | AY106: 0 | AZ106: 0 | BA106: 0 | BB106: 0 | BC106: 0 | BD106: 0
A107: 46304 | B107: 106 | C107: LIB065 | D107: NW | E107: 0 | F107: 185 | G107: 0 | H107: PP0651026 | J107: WST | L107: T:\MINA\Drill and blast\Deswik\MB_CP_MVV_final.gmdlb | O107: II | P107: Pre-Splitting | X107: Sandvik DP1500i | Z107: Planned | AB107: 5 | AC107: 748688.52 | AD107: 8930441.2 | AE107: 189.57 | AF107: 748689.76 | AG107: 8930440.7 | AH107: 185 | AI107: 4.76 | AJ107: 0 | AK107: 1.5 | AL107: 0.8 | AM107: 112.03 | AN107: 16.34 | AO107: 0 | AP107: 2.8 | AQ107: 0 | AR107: 0 | AS107: 0 | AT107: 0 | AU107: 0 | AV107: 0 | AW107: 0 | AX107: 0 | AY107: 0 | AZ107: 0 | BA107: 0 | BB107: 0 | BC107: 0 | BD107: 0
A108: 46304 | B108: 107 | C108: LIB065 | D108: NW | E108: 0 | F108: 185 | G108: 0 | H108: PP0651026 | J108: WST | L108: T:\MINA\Drill and blast\Deswik\MB_CP_MVV_final.gmdlb | O108: II | P108: Pre-Splitting | X108: Sandvik DP1500i | Z108: Planned | AB108: 5 | AC108: 748687.95 | AD108: 8930439.8 | AE108: 189.56 | AF108: 748689.19 | AG108: 8930439.3 | AH108: 185 | AI108: 4.75 | AJ108: 0 | AK108: 1.5 | AL108: 0.8 | AM108: 112.3 | AN108: 16.41 | AO108: 0 | AP108: 2.8 | AQ108: 0 | AR108: 0 | AS108: 0 | AT108: 0 | AU108: 0 | AV108: 0 | AW108: 0 | AX108: 0 | AY108: 0 | AZ108: 0 | BA108: 0 | BB108: 0 | BC108: 0 | BD108: 0
A109: 46304 | B109: 108 | C109: LIB065 | D109: NW | E109: 0 | F109: 185 | G109: 0 | H109: PP0651026 | J109: WST | L109: T:\MINA\Drill and blast\Deswik\MB_CP_MVV_final.gmdlb | O109: II | P109: Pre-Splitting | X109: Sandvik DP1500i | Z109: Planned | AB109: 5 | AC109: 748687.33 | AD109: 8930438.5 | AE109: 189.5 | AF109: 748688.55 | AG109: 8930437.9 | AH109: 185 | AI109: 4.7 | AJ109: 0 | AK109: 1.5 | AL109: 0.8 | AM109: 114.62 | AN109: 16.61 | AO109: 0 | AP109: 2.79 | AQ109: 0 | AR109: 0 | AS109: 0 | AT109: 0 | AU109: 0 | AV109: 0 | AW109: 0 | AX109: 0 | AY109: 0 | AZ109: 0 | BA109: 0 | BB109: 0 | BC109: 0 | BD109: 0
A110: 46304 | B110: 109 | C110: LIB065 | D110: NW | E110: 0 | F110: 185 | G110: 0 | H110: PP0651026 | J110: WST | L110: T:\MINA\Drill and blast\Deswik\MB_CP_MVV_final.gmdlb | O110: II | P110: Pre-Splitting | X110: Sandvik DP1500i | Z110: Planned | AB110: 5 | AC110: 748686.59 | AD110: 8930437.2 | AE110: 189.45 | AF110: 748687.76 | AG110: 8930436.5 | AH110: 185 | AI110: 4.65 | AJ110: 0 | AK110: 1.5 | AL110: 0.8 | AM110: 119.29 | AN110: 16.84 | AO110: 0 | AP110: 2.79 | AQ110: 0 | AR110: 0 | AS110: 0 | AT110: 0 | AU110: 0 | AV110: 0 | AW110: 0 | AX110: 0 | AY110: 0 | AZ110: 0 | BA110: 0 | BB110: 0 | BC110: 0 | BD110: 0
A111: 46304 | B111: 110 | C111: LIB065 | D111: NW | E111: 0 | F111: 185 | G111: 0 | H111: PP0651026 | J111: WST | L111: T:\MINA\Drill and blast\Deswik\MB_CP_MVV_final.gmdlb | O111: II | P111: Pre-Splitting | X111: Sandvik DP1500i | Z111: Planned | AB111: 5 | AC111: 748685.85 | AD111: 8930435.8 | AE111: 189.35 | AF111: 748687.03 | AG111: 8930435.2 | AH111: 185 | AI111: 4.55 | AJ111: 0 | AK111: 1.5 | AL111: 0.8 | AM111: 119.29 | AN111: 17.24 | AO111: 0 | AP111: 2.79 | AQ111: 0 | AR111: 0 | AS111: 0 | AT111: 0 | AU111: 0 | AV111: 0 | AW111: 0 | AX111: 0 | AY111: 0 | AZ111: 0 | BA111: 0 | BB111: 0 | BC111: 0 | BD111: 0
A112: 46304 | B112: 111 | C112: LIB065 | D112: NW | E112: 0 | F112: 185 | G112: 0 | H112: PP0651026 | J112: WST | L112: T:\MINA\Drill and blast\Deswik\MB_CP_MVV_final.gmdlb | O112: II | P112: Pre-Splitting | X112: Sandvik DP1500i | Z112: Planned | AB112: 5 | AC112: 748684.99 | AD112: 8930434.6 | AE112: 189.28 | AF112: 748686.08 | AG112: 8930433.8 | AH112: 185 | AI112: 4.48 | AJ112: 0 | AK112: 1.5 | AL112: 0.8 | AM112: 125.42 | AN112: 17.46 | AO112: 0 | AP112: 2.79 | AQ112: 0 | AR112: 0 | AS112: 0 | AT112: 0 | AU112: 0 | AV112: 0 | AW112: 0 | AX112: 0 | AY112: 0 | AZ112: 0 | BA112: 0 | BB112: 0 | BC112: 0 | BD112: 0
A113: 46304 | B113: 112 | C113: LIB065 | D113: NW | E113: 0 | F113: 185 | G113: 0 | H113: PP0651026 | J113: WST | L113: T:\MINA\Drill and blast\Deswik\MB_CP_MVV_final.gmdlb | O113: II | P113: Pre-Splitting | X113: Sandvik DP1500i | Z113: Planned | AB113: 5 | AC113: 748684.08 | AD113: 8930433.4 | AE113: 189.18 | AF113: 748685.15 | AG113: 8930432.6 | AH113: 185 | AI113: 4.39 | AJ113: 0 | AK113: 1.5 | AL113: 0.8 | AM113: 127.11 | AN113: 17.84 | AO113: 0 | AP113: 2.79 | AQ113: 0 | AR113: 0 | AS113: 0 | AT113: 0 | AU113: 0 | AV113: 0 | AW113: 0 | AX113: 0 | AY113: 0 | AZ113: 0 | BA113: 0 | BB113: 0 | BC113: 0 | BD113: 0
A114: 46304 | B114: 113 | C114: LIB065 | D114: NW | E114: 0 | F114: 185 | G114: 0 | H114: PP0651026 | J114: WST | L114: T:\MINA\Drill and blast\Deswik\MB_CP_MVV_final.gmdlb | O114: II | P114: Pre-Splitting | X114: Sandvik DP1500i | Z114: Planned | AB114: 5 | AC114: 748683.13 | AD114: 8930432.3 | AE114: 189.17 | AF114: 748684.18 | AG114: 8930431.4 | AH114: 185 | AI114: 4.38 | AJ114: 0 | AK114: 1.5 | AL114: 0.8 | AM114: 129.32 | AN114: 18.01 | AO114: 0 | AP114: 2.79 | AQ114: 0 | AR114: 0 | AS114: 0 | AT114: 0 | AU114: 0 | AV114: 0 | AW114: 0 | AX114: 0 | AY114: 0 | AZ114: 0 | BA114: 0 | BB114: 0 | BC114: 0 | BD114: 0
A115: 46304 | B115: 114 | C115: LIB065 | D115: NW | E115: 0 | F115: 185 | G115: 0 | H115: PP0651026 | J115: WST | L115: T:\MINA\Drill and blast\Deswik\MB_CP_MVV_final.gmdlb | O115: II | P115: Pre-Splitting | X115: Sandvik DP1500i | Z115: Planned | AB115: 5 | AC115: 748682.06 | AD115: 8930431.2 | AE115: 189.22 | AF115: 748683 | AG115: 8930430.2 | AH115: 185 | AI115: 4.43 | AJ115: 0 | AK115: 1.5 | AL115: 0.8 | AM115: 135.46 | AN115: 17.71 | AO115: 0 | AP115: 2.79 | AQ115: 0 | AR115: 0 | AS115: 0 | AT115: 0 | AU115: 0 | AV115: 0 | AW115: 0 | AX115: 0 | AY115: 0 | AZ115: 0 | BA115: 0 | BB115: 0 | BC115: 0 | BD115: 0
... A117: 46304 | B117: 116 | C117: LIB065 | D117: NW | E117: 0 | F117: 185 | G117: 0 | H117: PP0651026 | J117: WST | L117: T:\MINA\Drill and blast\Deswik\MB_CP_MVV_final.gmdlb | O117: II | P117: Pre-Splitting | X117: Sandvik DP1500i | Z117: Planned | AB117: 5 | AC117: 748679.82 | AD117: 8930429.2 | AE117: 189.47 | AF117: 748680.66 | AG117: 8930428.2 | AH117: 185 | AI117: 4.67 | AJ117: 0 | AK117: 1.5 | AL117: 0.8 | AM117: 141.42 | AN117: 16.79 | AO117: 0 | AP117: 2.78 | AQ117: 0 | AR117: 0 | AS117: 0 | AT117: 0 | AU117: 0 | AV117: 0 | AW117: 0 | AX117: 0 | AY117: 0 | AZ117: 0 | BA117: 0 | BB117: 0 | BC117: 0 | BD117: 0
A118: 46304 | B118: 117 | C118: LIB065 | D118: NW | E118: 2 | F118: 184 | G118: 0 | H118: PP0651026 | I118: Gabbro | J118: WST | K118: NA | L118: T:\MINA\Drill and blast\Deswik\MB_CP_MVV_final.gmdlb | M118: R1 | O118: II | P118: Production | Q118: Emulsao 1.15g/cm3 | R118: 1 Booster 450g | S118: 1 Esp Elet | T118: 1 Esp n Elet | X118: Sandvik DP1500i | Z118: Planned | AA118: Tampao 1.5m + 1m Air Deck | AB118: 5 | AC118: 748678.87 | AD118: 8930425.2 | AE118: 189.74 | AF118: 748678.87 | AG118: 8930425.2 | AH118: 184.4 | AI118: 5.34 | AJ118: 0.6 | AK118: 2.97 | AL118: 2.58 | AM118: 0 | AN118: 0 | AO118: 358 | AP118: 2.78 | AQ118: 0 | AR118: 0 | AS118: 0 | AT118: 0 | AU118: 0 | AV118: 0 | AW118: 0 | AX118: 0 | AY118: 2.5 | AZ118: 41.35 | BA118: 0 | BB118: 0 | BC118: 0 | BD118: 0
A119: 46304 | B119: 118 | C119: LIB065 | D119: NW | E119: 2 | F119: 184 | G119: 0 | H119: PP0651026 | I119: Gabbro | J119: WST | K119: NA | L119: T:\MINA\Drill and blast\Deswik\MB_CP_MVV_final.gmdlb | M119: R1 | O119: II | P119: Production | Q119: Emulsao 1.15g/cm3 | R119: 1 Booster 450g | S119: 1 Esp Elet | T119: 1 Esp n Elet | X119: Sandvik DP1500i | Z119: Planned | AA119: Tampao 1.5m + 1m Air Deck | AB119: 5 | AC119: 748680.93 | AD119: 8930426.7 | AE119: 189.27 | AF119: 748680.93 | AG119: 8930426.7 | AH119: 184.4 | AI119: 4.87 | AJ119: 0.6 | AK119: 2.97 | AL119: 2.58 | AM119: 0 | AN119: 0 | AO119: 358 | AP119: 2.78 | AQ119: 0 | AR119: 0 | AS119: 0 | AT119: 0 | AU119: 0 | AV119: 0 | AW119: 0 | AX119: 0 | AY119: 2.5 | AZ119: 34.507 | BA119: 0 | BB119: 0 | BC119: 0 | BD119: 0
A120: 46304 | B120: 119 | C120: LIB065 | D120: NW | E120: 2 | F120: 184 | G120: 0 | H120: PP0651026 | I120: Gabbro | J120: WST | K120: NA | L120: T:\MINA\Drill and blast\Deswik\MB_CP_MVV_final.gmdlb | M120: R1 | O120: II | P120: Production | Q120: Emulsao 1.15g/cm3 | R120: 1 Booster 450g | S120: 1 Esp Elet | T120: 1 Esp n Elet | X120: Sandvik DP1500i | Z120: Planned | AA120: Tampao 1.5m + 1m Air Deck | AB120: 5 | AC120: 748683.22 | AD120: 8930428.6 | AE120: 189.06 | AF120: 748683.22 | AG120: 8930428.6 | AH120: 184.4 | AI120: 4.66 | AJ120: 0.6 | AK120: 2.97 | AL120: 2.58 | AM120: 0 | AN120: 0 | AO120: 358 | AP120: 2.79 | AQ120: 0 | AR120: 0 | AS120: 0 | AT120: 0 | AU120: 0 | AV120: 0 | AW120: 0 | AX120: 0 | AY120: 2.5 | AZ120: 31.45 | BA120: 0 | BB120: 0 | BC120: 0 | BD120: 0
A121: 46304 | B121: 120 | C121: LIB065 | D121: NW | E121: 2 | F121: 184 | G121: 0 | H121: PP0651026 | I121: Gabbro | J121: WST | K121: NA | L121: T:\MINA\Drill and blast\Deswik\MB_CP_MVV_final.gmdlb | M121: R1 | O121: II | P121: Production | Q121: Emulsao 1.15g/cm3 | R121: 1 Booster 450g | S121: 1 Esp Elet | T121: 1 Esp n Elet | X121: Sandvik DP1500i | Z121: Planned | AA121: Tampao 1.5m + 1m Air Deck | AB121: 5 | AC121: 748685.34 | AD121: 8930430.7 | AE121: 189.08 | AF121: 748685.34 | AG121: 8930430.7 | AH121: 184.4 | AI121: 4.68 | AJ121: 0.6 | AK121: 2.97 | AL121: 2.58 | AM121: 0 | AN121: 0 | AO121: 358 | AP121: 2.79 | AQ121: 0 | AR121: 0 | AS121: 0 | AT121: 0 | AU121: 0 | AV121: 0 | AW121: 0 | AX121: 0 | AY121: 2.5 | AZ121: 31.741 | BA121: 0 | BB121: 0 | BC121: 0 | BD121: 0
A122: 46304 | B122: 121 | C122: LIB065 | D122: NW | E122: 2 | F122: 184 | G122: 0 | H122: PP0651026 | I122: Gabbro | J122: WST | K122: NA | L122: T:\MINA\Drill and blast\Deswik\MB_CP_MVV_final.gmdlb | M122: R1 | O122: II | P122: Production | Q122: Emulsao 1.15g/cm3 | R122: 1 Booster 450g | S122: 1 Esp Elet | T122: 1 Esp n Elet | X122: Sandvik DP1500i | Z122: Planned | AA122: Tampao 2.3m + 1m Air Deck | AB122: 5 | AC122: 748687.14 | AD122: 8930433 | AE122: 189.21 | AF122: 748687.14 | AG122: 8930433 | AH122: 184.4 | AI122: 4.81 | AJ122: 0.6 | AK122: 2.97 | AL122: 2.58 | AM122: 0 | AN122: 0 | AO122: 358 | AP122: 2.79 | AQ122: 0 | AR122: 0 | AS122: 0 | AT122: 0 | AU122: 0 | AV122: 0 | AW122: 0 | AX122: 0 | AY122: 3.3 | AZ122: 21.986 | BA122: 0 | BB122: 0 | BC122: 0 | BD122: 0
A123: 46304 | B123: 122 | C123: LIB065 | D123: NW | E123: 2 | F123: 184 | G123: 0 | H123: PP0651026 | I123: Gneiss | J123: WST | K123: NA | L123: T:\MINA\Drill and blast\Deswik\MB_CP_MVV_final.gmdlb | M123: R1 | O123: II | P123: Production | Q123: Emulsao 1.15g/cm3 | R123: 1 Booster 450g | S123: 1 Esp Elet | T123: 1 Esp n Elet | X123: Sandvik DP1500i | Z123: Planned | AA123: Tampao 1.5m + 1m Air Deck | AB123: 5 | AC123: 748688.75 | AD123: 8930435.5 | AE123: 189.41 | AF123: 748688.75 | AG123: 8930435.5 | AH123: 184.4 | AI123: 5.01 | AJ123: 0.6 | AK123: 2.97 | AL123: 2.58 | AM123: 0 | AN123: 0 | AO123: 358 | AP123: 2.79 | AQ123: 0 | AR123: 0 | AS123: 0 | AT123: 0 | AU123: 0 | AV123: 0 | AW123: 0 | AX123: 0 | AY123: 2.5 | AZ123: 36.546 | BA123: 0 | BB123: 0 | BC123: 0 | BD123: 0
A124: 46304 | B124: 123 | C124: LIB065 | D124: NW | E124: 2 | F124: 184 | G124: 0 | H124: PP0651026 | I124: Gneiss | J124: WST | K124: NA | L124: T:\MINA\Drill and blast\Deswik\MB_CP_MVV_final.gmdlb | M124: R1 | O124: II | P124: Production | Q124: Emulsao 1.15g/cm3 | R124: 1 Booster 450g | S124: 1 Esp Elet | T124: 1 Esp n Elet | X124: Sandvik DP1500i | Z124: Planned | AA124: Tampao 1.5m + 1m Air Deck | AB124: 5 | AC124: 748690.15 | AD124: 8930438.2 | AE124: 189.62 | AF124: 748690.15 | AG124: 8930438.2 | AH124: 184.4 | AI124: 5.22 | AJ124: 0.6 | AK124: 2.97 | AL124: 2.58 | AM124: 0 | AN124: 0 | AO124: 358 | AP124: 2.79 | AQ124: 0 | AR124: 0 | AS124: 0 | AT124: 0 | AU124: 0 | AV124: 0 | AW124: 0 | AX124: 0 | AY124: 2.5 | AZ124: 39.603 | BA124: 0 | BB124: 0 | BC124: 0 | BD124: 0
A125: 46304 | B125: 124 | C125: LIB065 | D125: NW | E125: 2 | F125: 184 | G125: 0 | H125: PP0651026 | I125: Gneiss | J125: WST | K125: NA | L125: T:\MINA\Drill and blast\Deswik\MB_CP_MVV_final.gmdlb | M125: R1 | O125: II | P125: Production | Q125: Emulsao 1.15g/cm3 | R125: 1 Booster 450g | S125: 1 Esp Elet | T125: 1 Esp n Elet | X125: Sandvik DP1500i | Z125: Planned | AA125: Tampao 1.5m + 1m Air Deck | AB125: 5 | AC125: 748691.28 | AD125: 8930440.9 | AE125: 189.6 | AF125: 748691.28 | AG125: 8930440.9 | AH125: 184.4 | AI125: 5.2 | AJ125: 0.6 | AK125: 2.97 | AL125: 2.58 | AM125: 0 | AN125: 0 | AO125: 358 | AP125: 2.81 | AQ125: 0 | AR125: 0 | AS125: 0 | AT125: 0 | AU125: 0 | AV125: 0 | AW125: 0 | AX125: 0 | AY125: 2.5 | AZ125: 39.312 | BA125: 0 | BB125: 0 | BC125: 0 | BD125: 0
A126: 46304 | B126: 125 | C126: LIB065 | D126: NW | E126: 2 | F126: 184 | G126: 0 | H126: PP0651026 | I126: Gneiss | J126: WST | K126: NA | L126: T:\MINA\Drill and blast\Deswik\MB_CP_MVV_final.gmdlb | M126: R1 | O126: II | P126: Production | Q126: Emulsao 1.15g/cm3 | R126: 1 Booster 450g | S126: 1 Esp Elet | T126: 1 Esp n Elet | X126: Sandvik DP1500i | Z126: Planned | AA126: Tampao 1.5m + 1m Air Deck | AB126: 5 | AC126: 748692.19 | AD126: 8930443.7 | AE126: 189.6 | AF126: 748692.19 | AG126: 8930443.7 | AH126: 184.4 | AI126: 5.2 | AJ126: 0.6 | AK126: 2.97 | AL126: 2.58 | AM126: 0 | AN126: 0 | AO126: 358 | AP126: 2.82 | AQ126: 0 | AR126: 0 | AS126: 0 | AT126: 0 | AU126: 0 | AV126: 0 | AW126: 0 | AX126: 0 | AY126: 2.5 | AZ126: 39.312 | BA126: 0 | BB126: 0 | BC126: 0 | BD126: 0
A127: 46304 | B127: 126 | C127: LIB065 | D127: NW | E127: 2 | F127: 184 | G127: 0 | H127: PP0651026 | I127: Gneiss | J127: WST | K127: NA | L127: T:\MINA\Drill and blast\Deswik\MB_CP_MVV_final.gmdlb | M127: R1 | O127: II | P127: Production | Q127: Emulsao 1.15g/cm3 | R127: 1 Booster 450g | S127: 1 Esp Elet | T127: 1 Esp n Elet | X127: Sandvik DP1500i | Z127: Planned | AA127: Tampao 1.5m + 1m Air Deck | AB127: 5 | AC127: 748693.25 | AD127: 8930446.5 | AE127: 189.69 | AF127: 748693.25 | AG127: 8930446.5 | AH127: 184.4 | AI127: 5.29 | AJ127: 0.6 | AK127: 2.97 | AL127: 2.58 | AM127: 0 | AN127: 0 | AO127: 358 | AP127: 2.82 | AQ127: 0 | AR127: 0 | AS127: 0 | AT127: 0 | AU127: 0 | AV127: 0 | AW127: 0 | AX127: 0 | AY127: 2.5 | AZ127: 40.622 | BA127: 0 | BB127: 0 | BC127: 0 | BD127: 0
A128: 46304 | B128: 127 | C128: LIB065 | D128: NW | E128: 2 | F128: 184 | G128: 0 | H128: PP0651026 | I128: Gneiss | J128: WST | K128: NA | L128: T:\MINA\Drill and blast\Deswik\MB_CP_MVV_final.gmdlb | M128: R1 | O128: II | P128: Production | Q128: Emulsao 1.15g/cm3 | R128: 1 Booster 450g | S128: 1 Esp Elet | T128: 1 Esp n Elet | X128: Sandvik DP1500i | Z128: Planned | AA128: Tampao 1.5m + 1m Air Deck | AB128: 5 | AC128: 748694.77 | AD128: 8930449 | AE128: 189.71 | AF128: 748694.77 | AG128: 8930449 | AH128: 184.4 | AI128: 5.31 | AJ128: 0.6 | AK128: 2.97 | AL128: 2.58 | AM128: 0 | AN128: 0 | AO128: 358 | AP128: 2.82 | AQ128: 0 | AR128: 0 | AS128: 0 | AT128: 0 | AU128: 0 | AV128: 0 | AW128: 0 | AX128: 0 | AY128: 2.5 | AZ128: 40.914 | BA128: 0 | BB128: 0 | BC128: 0 | BD128: 0
A129: 46304 | B129: 128 | C129: LIB065 | D129: NW | E129: 2 | F129: 184 | G129: 0 | H129: PP0651026 | I129: Gneiss | J129: WST | K129: NA | L129: T:\MINA\Drill and blast\Deswik\MB_CP_MVV_final.gmdlb | M129: R1 | O129: II | P129: Production | Q129: Emulsao 1.15g/cm3 | R129: 1 Booster 450g | S129: 1 Esp Elet | T129: 1 Esp n Elet | X129: Sandvik DP1500i | Z129: Planned | AA129: Tampao 1.5m + 1m Air Deck | AB129: 5 | AC129: 748696.29 | AD129: 8930451.6 | AE129: 189.81 | AF129: 748696.29 | AG129: 8930451.6 | AH129: 184.4 | AI129: 5.41 | AJ129: 0.6 | AK129: 2.97 | AL129: 2.58 | AM129: 0 | AN129: 0 | AO129: 358 | AP129: 2.83 | AQ129: 0 | AR129: 0 | AS129: 0 | AT129: 0 | AU129: 0 | AV129: 0 | AW129: 0 | AX129: 0 | AY129: 2.5 | AZ129: 42.37 | BA129: 0 | BB129: 0 | BC129: 0 | BD129: 0
... A283: 46304 | B283: 282 | C283: LIB065 | D283: NW | E283: 2 | F283: 185 | G283: 1 | H283: PP0651026 | I283: Magnetite-Norite | J283: ORE_MG_TP1_D1 | K283: F3 | L283: T:\MINA\Drill and blast\Deswik\MB_CP_MVV_final.gmdlb | M283: R5 | O283: II | P283: Production | Q283: Emulsao 1.15g/cm3 | R283: 1 Booster 450g | S283: 1 Esp Elet | T283: 1 Esp n Elet | X283: Sandvik DP1500i | Z283: Planned | AA283: Tampao 1.5m + 1m Air Deck | AB283: 5 | AC283: 748719.41 | AD283: 8930490.8 | AE283: 189.43 | AF283: 748719.41 | AG283: 8930490.8 | AH283: 184.68 | AI283: 4.75 | AJ283: 0.6 | AK283: 2.97 | AL283: 2.58 | AM283: 0 | AN283: 0 | AO283: 358 | AP283: 3.34 | AQ283: 0.7 | AR283: 0.11 | AS283: 0.09 | AT283: 19.83 | AU283: 5.89 | AV283: 0.36 | AW283: 1.95 | AX283: 8.38 | AY283: 2.5 | AZ283: 32.76 | BA283: 0 | BB283: 0 | BC283: 0 | BD283: 0
...

Sheet LEV R&D

Sheet MEDIÇÃO
B1: ='PROJETO PERFURAÇÃO'!$C$2&" - "&'PROJETO PERFURAÇÃO'!$H$2 -> LIB065 - PP0651026 | I1: P | J1: =Produção
I2: B | J2: =Buffer
I3: S | J3: =Pré Corte
B4: Ø | C4: Type | D4: ID | E4: Obj | F4: Inc | G4: Perf | H4: Rep | I4: Ø | J4: Type | K4: ID | L4: Obj | M4: Inc | N4: Perf | O4: Rep | P4: Ø | Q4: Type | R4: ID | S4: Obj | T4: Inc | U4: Perf | V4: Rep
B5: =IFERROR(ROUND(INDEX('PROJETO PERFURAÇÃO'!$AB:$AB,MATCH(MEDIÇÃO!D5,'PROJETO PERFURAÇÃO'!$B:$B,0)),1)&"''","") -> 5'' | C5: =IFERROR(IF(INDEX('PROJETO PERFURAÇÃO'!$P:$P,MATCH(MEDIÇÃO!D5,'PROJETO PERFURAÇÃO'!$B:$B,0))="Production","P",IF(INDEX('PROJETO PERFURAÇÃO'!$P:$P,MATCH(MEDIÇÃO!D5,'PROJETO PERFURAÇÃO'!$B:$B,0))="Buffer","B",IF(INDEX('PROJETO PERFURAÇÃO'!$P:$P,MATCH(MEDIÇÃO!D5,'PROJETO PERFURAÇÃO'!$B:$B,0))="Pre-Splitting","S"))),"") -> S | D5: 1 | E5: =IFERROR(INDEX('LEV R&D'!$D:$D,MATCH(MEDIÇÃO!D5,'LEV R&D'!$A:$A,0))-INDEX('PROJETO PERFURAÇÃO'!$AH:$AH,MATCH(MEDIÇÃO!D5,'PROJETO PERFURAÇÃO'!$B:$B,0)),"") | F5: =IFERROR(INDEX('PROJETO PERFURAÇÃO'!$AN:$AN,MATCH(MEDIÇÃO!D5,'PROJETO PERFURAÇÃO'!$B:$B,0)),"") -> 15.56 | I5: =IFERROR(ROUND(INDEX('PROJETO PERFURAÇÃO'!$AB:$AB,MATCH(MEDIÇÃO!K5,'PROJETO PERFURAÇÃO'!$B:$B,0)),1)&"''","") -> 5'' | J5: =IFERROR(IF(INDEX('PROJETO PERFURAÇÃO'!$P:$P,MATCH(MEDIÇÃO!K5,'PROJETO PERFURAÇÃO'!$B:$B,0))="Production","P",IF(INDEX('PROJETO PERFURAÇÃO'!$P:$P,MATCH(MEDIÇÃO!K5,'PROJETO PERFURAÇÃO'!$B:$B,0))="Buffer","B",IF(INDEX('PROJETO PERFURAÇÃO'!$P:$P,MATCH(MEDIÇÃO!K5,'PROJETO PERFURAÇÃO'!$B:$B,0))="Pre-Splitting","S"))),"") -> S | K5: =D27+1 -> 24 | L5: =IFERROR(INDEX('LEV R&D'!$D:$D,MATCH(MEDIÇÃO!K5,'LEV R&D'!$A:$A,0))-INDEX('PROJETO PERFURAÇÃO'!$AH:$AH,MATCH(MEDIÇÃO!K5,'PROJETO PERFURAÇÃO'!$B:$B,0)),"") | M5: =IFERROR(INDEX('PROJETO PERFURAÇÃO'!$AN:$AN,MATCH(MEDIÇÃO!K5,'PROJETO PERFURAÇÃO'!$B:$B,0)),"") -> 13.47 | P5: =IFERROR(ROUND(INDEX('PROJETO PERFURAÇÃO'!$AB:$AB,MATCH(MEDIÇÃO!R5,'PROJETO PERFURAÇÃO'!$B:$B,0)),1)&"''","") -> 5'' | Q5: =IFERROR(IF(INDEX('PROJETO PERFURAÇÃO'!$P:$P,MATCH(MEDIÇÃO!R5,'PROJETO PERFURAÇÃO'!$B:$B,0))="Production","P",IF(INDEX('PROJETO PERFURAÇÃO'!$P:$P,MATCH(MEDIÇÃO!R5,'PROJETO PERFURAÇÃO'!$B:$B,0))="Buffer","B",IF(INDEX('PROJETO PERFURAÇÃO'!$P:$P,MATCH(MEDIÇÃO!R5,'PROJETO PERFURAÇÃO'!$B:$B,0))="Pre-Splitting","S"))),"") -> S | R5: =K27+1 -> 47 | S5: =IFERROR(INDEX('LEV R&D'!$D:$D,MATCH(MEDIÇÃO!R5,'LEV R&D'!$A:$A,0))-INDEX('PROJETO PERFURAÇÃO'!$AH:$AH,MATCH(MEDIÇÃO!R5,'PROJETO PERFURAÇÃO'!$B:$B,0)),"") | T5: =IFERROR(INDEX('PROJETO PERFURAÇÃO'!$AN:$AN,MATCH(MEDIÇÃO!R5,'PROJETO PERFURAÇÃO'!$B:$B,0)),"") -> 14.94
B6: =IFERROR(ROUND(INDEX('PROJETO PERFURAÇÃO'!$AB:$AB,MATCH(MEDIÇÃO!D6,'PROJETO PERFURAÇÃO'!$B:$B,0)),1)&"''","") -> 5'' | C6: =IFERROR(IF(INDEX('PROJETO PERFURAÇÃO'!$P:$P,MATCH(MEDIÇÃO!D6,'PROJETO PERFURAÇÃO'!$B:$B,0))="Production","P",IF(INDEX('PROJETO PERFURAÇÃO'!$P:$P,MATCH(MEDIÇÃO!D6,'PROJETO PERFURAÇÃO'!$B:$B,0))="Buffer","B",IF(INDEX('PROJETO PERFURAÇÃO'!$P:$P,MATCH(MEDIÇÃO!D6,'PROJETO PERFURAÇÃO'!$B:$B,0))="Pre-Splitting","S"))),"") -> S | D6: =D5+1 -> 2 | E6: =IFERROR(INDEX('LEV R&D'!$D:$D,MATCH(MEDIÇÃO!D6,'LEV R&D'!$A:$A,0))-INDEX('PROJETO PERFURAÇÃO'!$AH:$AH,MATCH(MEDIÇÃO!D6,'PROJETO PERFURAÇÃO'!$B:$B,0)),"") | F6: =IFERROR(INDEX('PROJETO PERFURAÇÃO'!$AN:$AN,MATCH(MEDIÇÃO!D6,'PROJETO PERFURAÇÃO'!$B:$B,0)),"") -> 15.65 | I6: =IFERROR(ROUND(INDEX('PROJETO PERFURAÇÃO'!$AB:$AB,MATCH(MEDIÇÃO!K6,'PROJETO PERFURAÇÃO'!$B:$B,0)),1)&"''","") -> 5'' | J6: =IFERROR(IF(INDEX('PROJETO PERFURAÇÃO'!$P:$P,MATCH(MEDIÇÃO!K6,'PROJETO PERFURAÇÃO'!$B:$B,0))="Production","P",IF(INDEX('PROJETO PERFURAÇÃO'!$P:$P,MATCH(MEDIÇÃO!K6,'PROJETO PERFURAÇÃO'!$B:$B,0))="Buffer","B",IF(INDEX('PROJETO PERFURAÇÃO'!$P:$P,MATCH(MEDIÇÃO!K6,'PROJETO PERFURAÇÃO'!$B:$B,0))="Pre-Splitting","S"))),"") -> S | K6: =K5+1 -> 25 | L6: =IFERROR(INDEX('LEV R&D'!$D:$D,MATCH(MEDIÇÃO!K6,'LEV R&D'!$A:$A,0))-INDEX('PROJETO PERFURAÇÃO'!$AH:$AH,MATCH(MEDIÇÃO!K6,'PROJETO PERFURAÇÃO'!$B:$B,0)),"") | M6: =IFERROR(INDEX('PROJETO PERFURAÇÃO'!$AN:$AN,MATCH(MEDIÇÃO!K6,'PROJETO PERFURAÇÃO'!$B:$B,0)),"") -> 13.44 | P6: =IFERROR(ROUND(INDEX('PROJETO PERFURAÇÃO'!$AB:$AB,MATCH(MEDIÇÃO!R6,'PROJETO PERFURAÇÃO'!$B:$B,0)),1)&"''","") -> 5'' | Q6: =IFERROR(IF(INDEX('PROJETO PERFURAÇÃO'!$P:$P,MATCH(MEDIÇÃO!R6,'PROJETO PERFURAÇÃO'!$B:$B,0))="Production","P",IF(INDEX('PROJETO PERFURAÇÃO'!$P:$P,MATCH(MEDIÇÃO!R6,'PROJETO PERFURAÇÃO'!$B:$B,0))="Buffer","B",IF(INDEX('PROJETO PERFURAÇÃO'!$P:$P,MATCH(MEDIÇÃO!R6,'PROJETO PERFURAÇÃO'!$B:$B,0))="Pre-Splitting","S"))),"") -> S | R6: =R5+1 -> 48 | S6: =IFERROR(INDEX('LEV R&D'!$D:$D,MATCH(MEDIÇÃO!R6,'LEV R&D'!$A:$A,0))-INDEX('PROJETO PERFURAÇÃO'!$AH:$AH,MATCH(MEDIÇÃO!R6,'PROJETO PERFURAÇÃO'!$B:$B,0)),"") | T6: =IFERROR(INDEX('PROJETO PERFURAÇÃO'!$AN:$AN,MATCH(MEDIÇÃO!R6,'PROJETO PERFURAÇÃO'!$B:$B,0)),"") -> 14.82
B7: =IFERROR(ROUND(INDEX('PROJETO PERFURAÇÃO'!$AB:$AB,MATCH(MEDIÇÃO!D7,'PROJETO PERFURAÇÃO'!$B:$B,0)),1)&"''","") -> 5'' | C7: =IFERROR(IF(INDEX('PROJETO PERFURAÇÃO'!$P:$P,MATCH(MEDIÇÃO!D7,'PROJETO PERFURAÇÃO'!$B:$B,0))="Production","P",IF(INDEX('PROJETO PERFURAÇÃO'!$P:$P,MATCH(MEDIÇÃO!D7,'PROJETO PERFURAÇÃO'!$B:$B,0))="Buffer","B",IF(INDEX('PROJETO PERFURAÇÃO'!$P:$P,MATCH(MEDIÇÃO!D7,'PROJETO PERFURAÇÃO'!$B:$B,0))="Pre-Splitting","S"))),"") -> S | D7: =D6+1 -> 3 | E7: =IFERROR(INDEX('LEV R&D'!$D:$D,MATCH(MEDIÇÃO!D7,'LEV R&D'!$A:$A,0))-INDEX('PROJETO PERFURAÇÃO'!$AH:$AH,MATCH(MEDIÇÃO!D7,'PROJETO PERFURAÇÃO'!$B:$B,0)),"") | F7: =IFERROR(INDEX('PROJETO PERFURAÇÃO'!$AN:$AN,MATCH(MEDIÇÃO!D7,'PROJETO PERFURAÇÃO'!$B:$B,0)),"") -> 15.66 | I7: =IFERROR(ROUND(INDEX('PROJETO PERFURAÇÃO'!$AB:$AB,MATCH(MEDIÇÃO!K7,'PROJETO PERFURAÇÃO'!$B:$B,0)),1)&"''","") -> 5'' | J7: =IFERROR(IF(INDEX('PROJETO PERFURAÇÃO'!$P:$P,MATCH(MEDIÇÃO!K7,'PROJETO PERFURAÇÃO'!$B:$B,0))="Production","P",IF(INDEX('PROJETO PERFURAÇÃO'!$P:$P,MATCH(MEDIÇÃO!K7,'PROJETO PERFURAÇÃO'!$B:$B,0))="Buffer","B",IF(INDEX('PROJETO PERFURAÇÃO'!$P:$P,MATCH(MEDIÇÃO!K7,'PROJETO PERFURAÇÃO'!$B:$B,0))="Pre-Splitting","S"))),"") -> S | K7: =K6+1 -> 26 | L7: =IFERROR(INDEX('LEV R&D'!$D:$D,MATCH(MEDIÇÃO!K7,'LEV R&D'!$A:$A,0))-INDEX('PROJETO PERFURAÇÃO'!$AH:$AH,MATCH(MEDIÇÃO!K7,'PROJETO PERFURAÇÃO'!$B:$B,0)),"") | M7: =IFERROR(INDEX('PROJETO PERFURAÇÃO'!$AN:$AN,MATCH(MEDIÇÃO!K7,'PROJETO PERFURAÇÃO'!$B:$B,0)),"") -> 13.47 | P7: =IFERROR(ROUND(INDEX('PROJETO PERFURAÇÃO'!$AB:$AB,MATCH(MEDIÇÃO!R7,'PROJETO PERFURAÇÃO'!$B:$B,0)),1)&"''","") -> 5'' | Q7: =IFERROR(IF(INDEX('PROJETO PERFURAÇÃO'!$P:$P,MATCH(MEDIÇÃO!R7,'PROJETO PERFURAÇÃO'!$B:$B,0))="Production","P",IF(INDEX('PROJETO PERFURAÇÃO'!$P:$P,MATCH(MEDIÇÃO!R7,'PROJETO PERFURAÇÃO'!$B:$B,0))="Buffer","B",IF(INDEX('PROJETO PERFURAÇÃO'!$P:$P,MATCH(MEDIÇÃO!R7,'PROJETO PERFURAÇÃO'!$B:$B,0))="Pre-Splitting","S"))),"") -> S | R7: =R6+1 -> 49 | S7: =IFERROR(INDEX('LEV R&D'!$D:$D,MATCH(MEDIÇÃO!R7,'LEV R&D'!$A:$A,0))-INDEX('PROJETO PERFURAÇÃO'!$AH:$AH,MATCH(MEDIÇÃO!R7,'PROJETO PERFURAÇÃO'!$B:$B,0)),"") | T7: =IFERROR(INDEX('PROJETO PERFURAÇÃO'!$AN:$AN,MATCH(MEDIÇÃO!R7,'PROJETO PERFURAÇÃO'!$B:$B,0)),"") -> 14.72
B8: =IFERROR(ROUND(INDEX('PROJETO PERFURAÇÃO'!$AB:$AB,MATCH(MEDIÇÃO!D8,'PROJETO PERFURAÇÃO'!$B:$B,0)),1)&"''","") -> 5'' | C8: =IFERROR(IF(INDEX('PROJETO PERFURAÇÃO'!$P:$P,MATCH(MEDIÇÃO!D8,'PROJETO PERFURAÇÃO'!$B:$B,0))="Production","P",IF(INDEX('PROJETO PERFURAÇÃO'!$P:$P,MATCH(MEDIÇÃO!D8,'PROJETO PERFURAÇÃO'!$B:$B,0))="Buffer","B",IF(INDEX('PROJETO PERFURAÇÃO'!$P:$P,MATCH(MEDIÇÃO!D8,'PROJETO PERFURAÇÃO'!$B:$B,0))="Pre-Splitting","S"))),"") -> S | D8: =D7+1 -> 4 | E8: =IFERROR(INDEX('LEV R&D'!$D:$D,MATCH(MEDIÇÃO!D8,'LEV R&D'!$A:$A,0))-INDEX('PROJETO PERFURAÇÃO'!$AH:$AH,MATCH(MEDIÇÃO!D8,'PROJETO PERFURAÇÃO'!$B:$B,0)),"") | F8: =IFERROR(INDEX('PROJETO PERFURAÇÃO'!$AN:$AN,MATCH(MEDIÇÃO!D8,'PROJETO PERFURAÇÃO'!$B:$B,0)),"") -> 15.6 | I8: =IFERROR(ROUND(INDEX('PROJETO PERFURAÇÃO'!$AB:$AB,MATCH(MEDIÇÃO!K8,'PROJETO PERFURAÇÃO'!$B:$B,0)),1)&"''","") -> 5'' | J8: =IFERROR(IF(INDEX('PROJETO PERFURAÇÃO'!$P:$P,MATCH(MEDIÇÃO!K8,'PROJETO PERFURAÇÃO'!$B:$B,0))="Production","P",IF(INDEX('PROJETO PERFURAÇÃO'!$P:$P,MATCH(MEDIÇÃO!K8,'PROJETO PERFURAÇÃO'!$B:$B,0))="Buffer","B",IF(INDEX('PROJETO PERFURAÇÃO'!$P:$P,MATCH(MEDIÇÃO!K8,'PROJETO PERFURAÇÃO'!$B:$B,0))="Pre-Splitting","S"))),"") -> S | K8: =K7+1 -> 27 | L8: =IFERROR(INDEX('LEV R&D'!$D:$D,MATCH(MEDIÇÃO!K8,'LEV R&D'!$A:$A,0))-INDEX('PROJETO PERFURAÇÃO'!$AH:$AH,MATCH(MEDIÇÃO!K8,'PROJETO PERFURAÇÃO'!$B:$B,0)),"") | M8: =IFERROR(INDEX('PROJETO PERFURAÇÃO'!$AN:$AN,MATCH(MEDIÇÃO!K8,'PROJETO PERFURAÇÃO'!$B:$B,0)),"") -> 13.35 | P8: =IFERROR(ROUND(INDEX('PROJETO PERFURAÇÃO'!$AB:$AB,MATCH(MEDIÇÃO!R8,'PROJETO PERFURAÇÃO'!$B:$B,0)),1)&"''","") -> 5'' | Q8: =IFERROR(IF(INDEX('PROJETO PERFURAÇÃO'!$P:$P,MATCH(MEDIÇÃO!R8,'PROJETO PERFURAÇÃO'!$B:$B,0))="Production","P",IF(INDEX('PROJETO PERFURAÇÃO'!$P:$P,MATCH(MEDIÇÃO!R8,'PROJETO PERFURAÇÃO'!$B:$B,0))="Buffer","B",IF(INDEX('PROJETO PERFURAÇÃO'!$P:$P,MATCH(MEDIÇÃO!R8,'PROJETO PERFURAÇÃO'!$B:$B,0))="Pre-Splitting","S"))),"") -> S | R8: =R7+1 -> 50 | S8: =IFERROR(INDEX('LEV R&D'!$D:$D,MATCH(MEDIÇÃO!R8,'LEV R&D'!$A:$A,0))-INDEX('PROJETO PERFURAÇÃO'!$AH:$AH,MATCH(MEDIÇÃO!R8,'PROJETO PERFURAÇÃO'!$B:$B,0)),"") | T8: =IFERROR(INDEX('PROJETO PERFURAÇÃO'!$AN:$AN,MATCH(MEDIÇÃO!R8,'PROJETO PERFURAÇÃO'!$B:$B,0)),"") -> 14.61
B9: =IFERROR(ROUND(INDEX('PROJETO PERFURAÇÃO'!$AB:$AB,MATCH(MEDIÇÃO!D9,'PROJETO PERFURAÇÃO'!$B:$B,0)),1)&"''","") -> 5'' | C9: =IFERROR(IF(INDEX('PROJETO PERFURAÇÃO'!$P:$P,MATCH(MEDIÇÃO!D9,'PROJETO PERFURAÇÃO'!$B:$B,0))="Production","P",IF(INDEX('PROJETO PERFURAÇÃO'!$P:$P,MATCH(MEDIÇÃO!D9,'PROJETO PERFURAÇÃO'!$B:$B,0))="Buffer","B",IF(INDEX('PROJETO PERFURAÇÃO'!$P:$P,MATCH(MEDIÇÃO!D9,'PROJETO PERFURAÇÃO'!$B:$B,0))="Pre-Splitting","S"))),"") -> S | D9: =D8+1 -> 5 | E9: =IFERROR(INDEX('LEV R&D'!$D:$D,MATCH(MEDIÇÃO!D9,'LEV R&D'!$A:$A,0))-INDEX('PROJETO PERFURAÇÃO'!$AH:$AH,MATCH(MEDIÇÃO!D9,'PROJETO PERFURAÇÃO'!$B:$B,0)),"") | F9: =IFERROR(INDEX('PROJETO PERFURAÇÃO'!$AN:$AN,MATCH(MEDIÇÃO!D9,'PROJETO PERFURAÇÃO'!$B:$B,0)),"") -> 15.63 | I9: =IFERROR(ROUND(INDEX('PROJETO PERFURAÇÃO'!$AB:$AB,MATCH(MEDIÇÃO!K9,'PROJETO PERFURAÇÃO'!$B:$B,0)),1)&"''","") -> 5'' | J9: =IFERROR(IF(INDEX('PROJETO PERFURAÇÃO'!$P:$P,MATCH(MEDIÇÃO!K9,'PROJETO PERFURAÇÃO'!$B:$B,0))="Production","P",IF(INDEX('PROJETO PERFURAÇÃO'!$P:$P,MATCH(MEDIÇÃO!K9,'PROJETO PERFURAÇÃO'!$B:$B,0))="Buffer","B",IF(INDEX('PROJETO PERFURAÇÃO'!$P:$P,MATCH(MEDIÇÃO!K9,'PROJETO PERFURAÇÃO'!$B:$B,0))="Pre-Splitting","S"))),"") -> S | K9: =K8+1 -> 28 | L9: =IFERROR(INDEX('LEV R&D'!$D:$D,MATCH(MEDIÇÃO!K9,'LEV R&D'!$A:$A,0))-INDEX('PROJETO PERFURAÇÃO'!$AH:$AH,MATCH(MEDIÇÃO!K9,'PROJETO PERFURAÇÃO'!$B:$B,0)),"") | M9: =IFERROR(INDEX('PROJETO PERFURAÇÃO'!$AN:$AN,MATCH(MEDIÇÃO!K9,'PROJETO PERFURAÇÃO'!$B:$B,0)),"") -> 13.35 | P9: =IFERROR(ROUND(INDEX('PROJETO PERFURAÇÃO'!$AB:$AB,MATCH(MEDIÇÃO!R9,'PROJETO PERFURAÇÃO'!$B:$B,0)),1)&"''","") -> 5'' | Q9: =IFERROR(IF(INDEX('PROJETO PERFURAÇÃO'!$P:$P,MATCH(MEDIÇÃO!R9,'PROJETO PERFURAÇÃO'!$B:$B,0))="Production","P",IF(INDEX('PROJETO PERFURAÇÃO'!$P:$P,MATCH(MEDIÇÃO!R9,'PROJETO PERFURAÇÃO'!$B:$B,0))="Buffer","B",IF(INDEX('PROJETO PERFURAÇÃO'!$P:$P,MATCH(MEDIÇÃO!R9,'PROJETO PERFURAÇÃO'!$B:$B,0))="Pre-Splitting","S"))),"") -> S | R9: =R8+1 -> 51 | S9: =IFERROR(INDEX('LEV R&D'!$D:$D,MATCH(MEDIÇÃO!R9,'LEV R&D'!$A:$A,0))-INDEX('PROJETO PERFURAÇÃO'!$AH:$AH,MATCH(MEDIÇÃO!R9,'PROJETO PERFURAÇÃO'!$B:$B,0)),"") | T9: =IFERROR(INDEX('PROJETO PERFURAÇÃO'!$AN:$AN,MATCH(MEDIÇÃO!R9,'PROJETO PERFURAÇÃO'!$B:$B,0)),"") -> 14.38
B10: =IFERROR(ROUND(INDEX('PROJETO PERFURAÇÃO'!$AB:$AB,MATCH(MEDIÇÃO!D10,'PROJETO PERFURAÇÃO'!$B:$B,0)),1)&"''","") -> 5'' | C10: =IFERROR(IF(INDEX('PROJETO PERFURAÇÃO'!$P:$P,MATCH(MEDIÇÃO!D10,'PROJETO PERFURAÇÃO'!$B:$B,0))="Production","P",IF(INDEX('PROJETO PERFURAÇÃO'!$P:$P,MATCH(MEDIÇÃO!D10,'PROJETO PERFURAÇÃO'!$B:$B,0))="Buffer","B",IF(INDEX('PROJETO PERFURAÇÃO'!$P:$P,MATCH(MEDIÇÃO!D10,'PROJETO PERFURAÇÃO'!$B:$B,0))="Pre-Splitting","S"))),"") -> S | D10: =D9+1 -> 6 | E10: =IFERROR(INDEX('LEV R&D'!$D:$D,MATCH(MEDIÇÃO!D10,'LEV R&D'!$A:$A,0))-INDEX('PROJETO PERFURAÇÃO'!$AH:$AH,MATCH(MEDIÇÃO!D10,'PROJETO PERFURAÇÃO'!$B:$B,0)),"") | F10: =IFERROR(INDEX('PROJETO PERFURAÇÃO'!$AN:$AN,MATCH(MEDIÇÃO!D10,'PROJETO PERFURAÇÃO'!$B:$B,0)),"") -> 15.64 | I10: =IFERROR(ROUND(INDEX('PROJETO PERFURAÇÃO'!$AB:$AB,MATCH(MEDIÇÃO!K10,'PROJETO PERFURAÇÃO'!$B:$B,0)),1)&"''","") -> 5'' | J10: =IFERROR(IF(INDEX('PROJETO PERFURAÇÃO'!$P:$P,MATCH(MEDIÇÃO!K10,'PROJETO PERFURAÇÃO'!$B:$B,0))="Production","P",IF(INDEX('PROJETO PERFURAÇÃO'!$P:$P,MATCH(MEDIÇÃO!K10,'PROJETO PERFURAÇÃO'!$B:$B,0))="Buffer","B",IF(INDEX('PROJETO PERFURAÇÃO'!$P:$P,MATCH(MEDIÇÃO!K10,'PROJETO PERFURAÇÃO'!$B:$B,0))="Pre-Splitting","S"))),"") -> S | K10: =K9+1 -> 29 | L10: =IFERROR(INDEX('LEV R&D'!$D:$D,MATCH(MEDIÇÃO!K10,'LEV R&D'!$A:$A,0))-INDEX('PROJETO PERFURAÇÃO'!$AH:$AH,MATCH(MEDIÇÃO!K10,'PROJETO PERFURAÇÃO'!$B:$B,0)),"") | M10: =IFERROR(INDEX('PROJETO PERFURAÇÃO'!$AN:$AN,MATCH(MEDIÇÃO!K10,'PROJETO PERFURAÇÃO'!$B:$B,0)),"") -> 13.17 | P10: =IFERROR(ROUND(INDEX('PROJETO PERFURAÇÃO'!$AB:$AB,MATCH(MEDIÇÃO!R10,'PROJETO PERFURAÇÃO'!$B:$B,0)),1)&"''","") -> 5'' | Q10: =IFERROR(IF(INDEX('PROJETO PERFURAÇÃO'!$P:$P,MATCH(MEDIÇÃO!R10,'PROJETO PERFURAÇÃO'!$B:$B,0))="Production","P",IF(INDEX('PROJETO PERFURAÇÃO'!$P:$P,MATCH(MEDIÇÃO!R10,'PROJETO PERFURAÇÃO'!$B:$B,0))="Buffer","B",IF(INDEX('PROJETO PERFURAÇÃO'!$P:$P,MATCH(MEDIÇÃO!R10,'PROJETO PERFURAÇÃO'!$B:$B,0))="Pre-Splitting","S"))),"") -> S | R10: =R9+1 -> 52 | S10: =IFERROR(INDEX('LEV R&D'!$D:$D,MATCH(MEDIÇÃO!R10,'LEV R&D'!$A:$A,0))-INDEX('PROJETO PERFURAÇÃO'!$AH:$AH,MATCH(MEDIÇÃO!R10,'PROJETO PERFURAÇÃO'!$B:$B,0)),"") | T10: =IFERROR(INDEX('PROJETO PERFURAÇÃO'!$AN:$AN,MATCH(MEDIÇÃO!R10,'PROJETO PERFURAÇÃO'!$B:$B,0)),"") -> 14.52
B11: =IFERROR(ROUND(INDEX('PROJETO PERFURAÇÃO'!$AB:$AB,MATCH(MEDIÇÃO!D11,'PROJETO PERFURAÇÃO'!$B:$B,0)),1)&"''","") -> 5'' | C11: =IFERROR(IF(INDEX('PROJETO PERFURAÇÃO'!$P:$P,MATCH(MEDIÇÃO!D11,'PROJETO PERFURAÇÃO'!$B:$B,0))="Production","P",IF(INDEX('PROJETO PERFURAÇÃO'!$P:$P,MATCH(MEDIÇÃO!D11,'PROJETO PERFURAÇÃO'!$B:$B,0))="Buffer","B",IF(INDEX('PROJETO PERFURAÇÃO'!$P:$P,MATCH(MEDIÇÃO!D11,'PROJETO PERFURAÇÃO'!$B:$B,0))="Pre-Splitting","S"))),"") -> S | D11: =D10+1 -> 7 | E11: =IFERROR(INDEX('LEV R&D'!$D:$D,MATCH(MEDIÇÃO!D11,'LEV R&D'!$A:$A,0))-INDEX('PROJETO PERFURAÇÃO'!$AH:$AH,MATCH(MEDIÇÃO!D11,'PROJETO PERFURAÇÃO'!$B:$B,0)),"") | F11: =IFERROR(INDEX('PROJETO PERFURAÇÃO'!$AN:$AN,MATCH(MEDIÇÃO!D11,'PROJETO PERFURAÇÃO'!$B:$B,0)),"") -> 15.73 | I11: =IFERROR(ROUND(INDEX('PROJETO PERFURAÇÃO'!$AB:$AB,MATCH(MEDIÇÃO!K11,'PROJETO PERFURAÇÃO'!$B:$B,0)),1)&"''","") -> 5'' | J11: =IFERROR(IF(INDEX('PROJETO PERFURAÇÃO'!$P:$P,MATCH(MEDIÇÃO!K11,'PROJETO PERFURAÇÃO'!$B:$B,0))="Production","P",IF(INDEX('PROJETO PERFURAÇÃO'!$P:$P,MATCH(MEDIÇÃO!K11,'PROJETO PERFURAÇÃO'!$B:$B,0))="Buffer","B",IF(INDEX('PROJETO PERFURAÇÃO'!$P:$P,MATCH(MEDIÇÃO!K11,'PROJETO PERFURAÇÃO'!$B:$B,0))="Pre-Splitting","S"))),"") -> S | K11: =K10+1 -> 30 | L11: =IFERROR(INDEX('LEV R&D'!$D:$D,MATCH(MEDIÇÃO!K11,'LEV R&D'!$A:$A,0))-INDEX('PROJETO PERFURAÇÃO'!$AH:$AH,MATCH(MEDIÇÃO!K11,'PROJETO PERFURAÇÃO'!$B:$B,0)),"") | M11: =IFERROR(INDEX('PROJETO PERFURAÇÃO'!$AN:$AN,MATCH(MEDIÇÃO!K11,'PROJETO PERFURAÇÃO'!$B:$B,0)),"") -> 13.11 | P11: =IFERROR(ROUND(INDEX('PROJETO PERFURAÇÃO'!$AB:$AB,MATCH(MEDIÇÃO!R11,'PROJETO PERFURAÇÃO'!$B:$B,0)),1)&"''","") -> 5'' | Q11: =IFERROR(IF(INDEX('PROJETO PERFURAÇÃO'!$P:$P,MATCH(MEDIÇÃO!R11,'PROJETO PERFURAÇÃO'!$B:$B,0))="Production","P",IF(INDEX('PROJETO PERFURAÇÃO'!$P:$P,MATCH(MEDIÇÃO!R11,'PROJETO PERFURAÇÃO'!$B:$B,0))="Buffer","B",IF(INDEX('PROJETO PERFURAÇÃO'!$P:$P,MATCH(MEDIÇÃO!R11,'PROJETO PERFURAÇÃO'!$B:$B,0))="Pre-Splitting","S"))),"") -> S | R11: =R10+1 -> 53 | S11: =IFERROR(INDEX('LEV R&D'!$D:$D,MATCH(MEDIÇÃO!R11,'LEV R&D'!$A:$A,0))-INDEX('PROJETO PERFURAÇÃO'!$AH:$AH,MATCH(MEDIÇÃO!R11,'PROJETO PERFURAÇÃO'!$B:$B,0)),"") | T11: =IFERROR(INDEX('PROJETO PERFURAÇÃO'!$AN:$AN,MATCH(MEDIÇÃO!R11,'PROJETO PERFURAÇÃO'!$B:$B,0)),"") -> 14.77
B12: =IFERROR(ROUND(INDEX('PROJETO PERFURAÇÃO'!$AB:$AB,MATCH(MEDIÇÃO!D12,'PROJETO PERFURAÇÃO'!$B:$B,0)),1)&"''","") -> 5'' | C12: =IFERROR(IF(INDEX('PROJETO PERFURAÇÃO'!$P:$P,MATCH(MEDIÇÃO!D12,'PROJETO PERFURAÇÃO'!$B:$B,0))="Production","P",IF(INDEX('PROJETO PERFURAÇÃO'!$P:$P,MATCH(MEDIÇÃO!D12,'PROJETO PERFURAÇÃO'!$B:$B,0))="Buffer","B",IF(INDEX('PROJETO PERFURAÇÃO'!$P:$P,MATCH(MEDIÇÃO!D12,'PROJETO PERFURAÇÃO'!$B:$B,0))="Pre-Splitting","S"))),"") -> S | D12: =D11+1 -> 8 | E12: =IFERROR(INDEX('LEV R&D'!$D:$D,MATCH(MEDIÇÃO!D12,'LEV R&D'!$A:$A,0))-INDEX('PROJETO PERFURAÇÃO'!$AH:$AH,MATCH(MEDIÇÃO!D12,'PROJETO PERFURAÇÃO'!$B:$B,0)),"") | F12: =IFERROR(INDEX('PROJETO PERFURAÇÃO'!$AN:$AN,MATCH(MEDIÇÃO!D12,'PROJETO PERFURAÇÃO'!$B:$B,0)),"") -> 15.65 | I12: =IFERROR(ROUND(INDEX('PROJETO PERFURAÇÃO'!$AB:$AB,MATCH(MEDIÇÃO!K12,'PROJETO PERFURAÇÃO'!$B:$B,0)),1)&"''","") -> 5'' | J12: =IFERROR(IF(INDEX('PROJETO PERFURAÇÃO'!$P:$P,MATCH(MEDIÇÃO!K12,'PROJETO PERFURAÇÃO'!$B:$B,0))="Production","P",IF(INDEX('PROJETO PERFURAÇÃO'!$P:$P,MATCH(MEDIÇÃO!K12,'PROJETO PERFURAÇÃO'!$B:$B,0))="Buffer","B",IF(INDEX('PROJETO PERFURAÇÃO'!$P:$P,MATCH(MEDIÇÃO!K12,'PROJETO PERFURAÇÃO'!$B:$B,0))="Pre-Splitting","S"))),"") -> S | K12: =K11+1 -> 31 | L12: =IFERROR(INDEX('LEV R&D'!$D:$D,MATCH(MEDIÇÃO!K12,'LEV R&D'!$A:$A,0))-INDEX('PROJETO PERFURAÇÃO'!$AH:$AH,MATCH(MEDIÇÃO!K12,'PROJETO PERFURAÇÃO'!$B:$B,0)),"") | M12: =IFERROR(INDEX('PROJETO PERFURAÇÃO'!$AN:$AN,MATCH(MEDIÇÃO!K12,'PROJETO PERFURAÇÃO'!$B:$B,0)),"") -> 13.4 | P12: =IFERROR(ROUND(INDEX('PROJETO PERFURAÇÃO'!$AB:$AB,MATCH(MEDIÇÃO!R12,'PROJETO PERFURAÇÃO'!$B:$B,0)),1)&"''","") -> 5'' | Q12: =IFERROR(IF(INDEX('PROJETO PERFURAÇÃO'!$P:$P,MATCH(MEDIÇÃO!R12,'PROJETO PERFURAÇÃO'!$B:$B,0))="Production","P",IF(INDEX('PROJETO PERFURAÇÃO'!$P:$P,MATCH(MEDIÇÃO!R12,'PROJETO PERFURAÇÃO'!$B:$B,0))="Buffer","B",IF(INDEX('PROJETO PERFURAÇÃO'!$P:$P,MATCH(MEDIÇÃO!R12,'PROJETO PERFURAÇÃO'!$B:$B,0))="Pre-Splitting","S"))),"") -> S | R12: =R11+1 -> 54 | S12: =IFERROR(INDEX('LEV R&D'!$D:$D,MATCH(MEDIÇÃO!R12,'LEV R&D'!$A:$A,0))-INDEX('PROJETO PERFURAÇÃO'!$AH:$AH,MATCH(MEDIÇÃO!R12,'PROJETO PERFURAÇÃO'!$B:$B,0)),"") | T12: =IFERROR(INDEX('PROJETO PERFURAÇÃO'!$AN:$AN,MATCH(MEDIÇÃO!R12,'PROJETO PERFURAÇÃO'!$B:$B,0)),"") -> 14.75
B13: =IFERROR(ROUND(INDEX('PROJETO PERFURAÇÃO'!$AB:$AB,MATCH(MEDIÇÃO!D13,'PROJETO PERFURAÇÃO'!$B:$B,0)),1)&"''","") -> 5'' | C13: =IFERROR(IF(INDEX('PROJETO PERFURAÇÃO'!$P:$P,MATCH(MEDIÇÃO!D13,'PROJETO PERFURAÇÃO'!$B:$B,0))="Production","P",IF(INDEX('PROJETO PERFURAÇÃO'!$P:$P,MATCH(MEDIÇÃO!D13,'PROJETO PERFURAÇÃO'!$B:$B,0))="Buffer","B",IF(INDEX('PROJETO PERFURAÇÃO'!$P:$P,MATCH(MEDIÇÃO!D13,'PROJETO PERFURAÇÃO'!$B:$B,0))="Pre-Splitting","S"))),"") -> S | D13: =D12+1 -> 9 | E13: =IFERROR(INDEX('LEV R&D'!$D:$D,MATCH(MEDIÇÃO!D13,'LEV R&D'!$A:$A,0))-INDEX('PROJETO PERFURAÇÃO'!$AH:$AH,MATCH(MEDIÇÃO!D13,'PROJETO PERFURAÇÃO'!$B:$B,0)),"") | F13: =IFERROR(INDEX('PROJETO PERFURAÇÃO'!$AN:$AN,MATCH(MEDIÇÃO!D13,'PROJETO PERFURAÇÃO'!$B:$B,0)),"") -> 15.4 | I13: =IFERROR(ROUND(INDEX('PROJETO PERFURAÇÃO'!$AB:$AB,MATCH(MEDIÇÃO!K13,'PROJETO PERFURAÇÃO'!$B:$B,0)),1)&"''","") -> 5'' | J13: =IFERROR(IF(INDEX('PROJETO PERFURAÇÃO'!$P:$P,MATCH(MEDIÇÃO!K13,'PROJETO PERFURAÇÃO'!$B:$B,0))="Production","P",IF(INDEX('PROJETO PERFURAÇÃO'!$P:$P,MATCH(MEDIÇÃO!K13,'PROJETO PERFURAÇÃO'!$B:$B,0))="Buffer","B",IF(INDEX('PROJETO PERFURAÇÃO'!$P:$P,MATCH(MEDIÇÃO!K13,'PROJETO PERFURAÇÃO'!$B:$B,0))="Pre-Splitting","S"))),"") -> S | K13: =K12+1 -> 32 | L13: =IFERROR(INDEX('LEV R&D'!$D:$D,MATCH(MEDIÇÃO!K13,'LEV R&D'!$A:$A,0))-INDEX('PROJETO PERFURAÇÃO'!$AH:$AH,MATCH(MEDIÇÃO!K13,'PROJETO PERFURAÇÃO'!$B:$B,0)),"") | M13: =IFERROR(INDEX('PROJETO PERFURAÇÃO'!$AN:$AN,MATCH(MEDIÇÃO!K13,'PROJETO PERFURAÇÃO'!$B:$B,0)),"") -> 13.72 | P13: =IFERROR(ROUND(INDEX('PROJETO PERFURAÇÃO'!$AB:$AB,MATCH(MEDIÇÃO!R13,'PROJETO PERFURAÇÃO'!$B:$B,0)),1)&"''","") -> 5'' | Q13: =IFERROR(IF(INDEX('PROJETO PERFURAÇÃO'!$P:$P,MATCH(MEDIÇÃO!R13,'PROJETO PERFURAÇÃO'!$B:$B,0))="Production","P",IF(INDEX('PROJETO PERFURAÇÃO'!$P:$P,MATCH(MEDIÇÃO!R13,'PROJETO PERFURAÇÃO'!$B:$B,0))="Buffer","B",IF(INDEX('PROJETO PERFURAÇÃO'!$P:$P,MATCH(MEDIÇÃO!R13,'PROJETO PERFURAÇÃO'!$B:$B,0))="Pre-Splitting","S"))),"") -> S | R13: =R12+1 -> 55 | S13: =IFERROR(INDEX('LEV R&D'!$D:$D,MATCH(MEDIÇÃO!R13,'LEV R&D'!$A:$A,0))-INDEX('PROJETO PERFURAÇÃO'!$AH:$AH,MATCH(MEDIÇÃO!R13,'PROJETO PERFURAÇÃO'!$B:$B,0)),"") | T13: =IFERROR(INDEX('PROJETO PERFURAÇÃO'!$AN:$AN,MATCH(MEDIÇÃO!R13,'PROJETO PERFURAÇÃO'!$B:$B,0)),"") -> 14.69
B14: =IFERROR(ROUND(INDEX('PROJETO PERFURAÇÃO'!$AB:$AB,MATCH(MEDIÇÃO!D14,'PROJETO PERFURAÇÃO'!$B:$B,0)),1)&"''","") -> 5'' | C14: =IFERROR(IF(INDEX('PROJETO PERFURAÇÃO'!$P:$P,MATCH(MEDIÇÃO!D14,'PROJETO PERFURAÇÃO'!$B:$B,0))="Production","P",IF(INDEX('PROJETO PERFURAÇÃO'!$P:$P,MATCH(MEDIÇÃO!D14,'PROJETO PERFURAÇÃO'!$B:$B,0))="Buffer","B",IF(INDEX('PROJETO PERFURAÇÃO'!$P:$P,MATCH(MEDIÇÃO!D14,'PROJETO PERFURAÇÃO'!$B:$B,0))="Pre-Splitting","S"))),"") -> S | D14: =D13+1 -> 10 | E14: =IFERROR(INDEX('LEV R&D'!$D:$D,MATCH(MEDIÇÃO!D14,'LEV R&D'!$A:$A,0))-INDEX('PROJETO PERFURAÇÃO'!$AH:$AH,MATCH(MEDIÇÃO!D14,'PROJETO PERFURAÇÃO'!$B:$B,0)),"") | F14: =IFERROR(INDEX('PROJETO PERFURAÇÃO'!$AN:$AN,MATCH(MEDIÇÃO!D14,'PROJETO PERFURAÇÃO'!$B:$B,0)),"") -> 15.06 | I14: =IFERROR(ROUND(INDEX('PROJETO PERFURAÇÃO'!$AB:$AB,MATCH(MEDIÇÃO!K14,'PROJETO PERFURAÇÃO'!$B:$B,0)),1)&"''","") -> 5'' | J14: =IFERROR(IF(INDEX('PROJETO PERFURAÇÃO'!$P:$P,MATCH(MEDIÇÃO!K14,'PROJETO PERFURAÇÃO'!$B:$B,0))="Production","P",IF(INDEX('PROJETO PERFURAÇÃO'!$P:$P,MATCH(MEDIÇÃO!K14,'PROJETO PERFURAÇÃO'!$B:$B,0))="Buffer","B",IF(INDEX('PROJETO PERFURAÇÃO'!$P:$P,MATCH(MEDIÇÃO!K14,'PROJETO PERFURAÇÃO'!$B:$B,0))="Pre-Splitting","S"))),"") -> S | K14: =K13+1 -> 33 | L14: =IFERROR(INDEX('LEV R&D'!$D:$D,MATCH(MEDIÇÃO!K14,'LEV R&D'!$A:$A,0))-INDEX('PROJETO PERFURAÇÃO'!$AH:$AH,MATCH(MEDIÇÃO!K14,'PROJETO PERFURAÇÃO'!$B:$B,0)),"") | M14: =IFERROR(INDEX('PROJETO PERFURAÇÃO'!$AN:$AN,MATCH(MEDIÇÃO!K14,'PROJETO PERFURAÇÃO'!$B:$B,0)),"") -> 13.95 | P14: =IFERROR(ROUND(INDEX('PROJETO PERFURAÇÃO'!$AB:$AB,MATCH(MEDIÇÃO!R14,'PROJETO PERFURAÇÃO'!$B:$B,0)),1)&"''","") -> 5'' | Q14: =IFERROR(IF(INDEX('PROJETO PERFURAÇÃO'!$P:$P,MATCH(MEDIÇÃO!R14,'PROJETO PERFURAÇÃO'!$B:$B,0))="Production","P",IF(INDEX('PROJETO PERFURAÇÃO'!$P:$P,MATCH(MEDIÇÃO!R14,'PROJETO PERFURAÇÃO'!$B:$B,0))="Buffer","B",IF(INDEX('PROJETO PERFURAÇÃO'!$P:$P,MATCH(MEDIÇÃO!R14,'PROJETO PERFURAÇÃO'!$B:$B,0))="Pre-Splitting","S"))),"") -> S | R14: =R13+1 -> 56 | S14: =IFERROR(INDEX('LEV R&D'!$D:$D,MATCH(MEDIÇÃO!R14,'LEV R&D'!$A:$A,0))-INDEX('PROJETO PERFURAÇÃO'!$AH:$AH,MATCH(MEDIÇÃO!R14,'PROJETO PERFURAÇÃO'!$B:$B,0)),"") | T14: =IFERROR(INDEX('PROJETO PERFURAÇÃO'!$AN:$AN,MATCH(MEDIÇÃO!R14,'PROJETO PERFURAÇÃO'!$B:$B,0)),"") -> 14.56
B15: =IFERROR(ROUND(INDEX('PROJETO PERFURAÇÃO'!$AB:$AB,MATCH(MEDIÇÃO!D15,'PROJETO PERFURAÇÃO'!$B:$B,0)),1)&"''","") -> 5'' | C15: =IFERROR(IF(INDEX('PROJETO PERFURAÇÃO'!$P:$P,MATCH(MEDIÇÃO!D15,'PROJETO PERFURAÇÃO'!$B:$B,0))="Production","P",IF(INDEX('PROJETO PERFURAÇÃO'!$P:$P,MATCH(MEDIÇÃO!D15,'PROJETO PERFURAÇÃO'!$B:$B,0))="Buffer","B",IF(INDEX('PROJETO PERFURAÇÃO'!$P:$P,MATCH(MEDIÇÃO!D15,'PROJETO PERFURAÇÃO'!$B:$B,0))="Pre-Splitting","S"))),"") -> S | D15: =D14+1 -> 11 | E15: =IFERROR(INDEX('LEV R&D'!$D:$D,MATCH(MEDIÇÃO!D15,'LEV R&D'!$A:$A,0))-INDEX('PROJETO PERFURAÇÃO'!$AH:$AH,MATCH(MEDIÇÃO!D15,'PROJETO PERFURAÇÃO'!$B:$B,0)),"") | F15: =IFERROR(INDEX('PROJETO PERFURAÇÃO'!$AN:$AN,MATCH(MEDIÇÃO!D15,'PROJETO PERFURAÇÃO'!$B:$B,0)),"") -> 14.77 | I15: =IFERROR(ROUND(INDEX('PROJETO PERFURAÇÃO'!$AB:$AB,MATCH(MEDIÇÃO!K15,'PROJETO PERFURAÇÃO'!$B:$B,0)),1)&"''","") -> 5'' | J15: =IFERROR(IF(INDEX('PROJETO PERFURAÇÃO'!$P:$P,MATCH(MEDIÇÃO!K15,'PROJETO PERFURAÇÃO'!$B:$B,0))="Production","P",IF(INDEX('PROJETO PERFURAÇÃO'!$P:$P,MATCH(MEDIÇÃO!K15,'PROJETO PERFURAÇÃO'!$B:$B,0))="Buffer","B",IF(INDEX('PROJETO PERFURAÇÃO'!$P:$P,MATCH(MEDIÇÃO!K15,'PROJETO PERFURAÇÃO'!$B:$B,0))="Pre-Splitting","S"))),"") -> S | K15: =K14+1 -> 34 | L15: =IFERROR(INDEX('LEV R&D'!$D:$D,MATCH(MEDIÇÃO!K15,'LEV R&D'!$A:$A,0))-INDEX('PROJETO PERFURAÇÃO'!$AH:$AH,MATCH(MEDIÇÃO!K15,'PROJETO PERFURAÇÃO'!$B:$B,0)),"") | M15: =IFERROR(INDEX('PROJETO PERFURAÇÃO'!$AN:$AN,MATCH(MEDIÇÃO!K15,'PROJETO PERFURAÇÃO'!$B:$B,0)),"") -> 13.96 | P15: =IFERROR(ROUND(INDEX('PROJETO PERFURAÇÃO'!$AB:$AB,MATCH(MEDIÇÃO!R15,'PROJETO PERFURAÇÃO'!$B:$B,0)),1)&"''","") -> 5'' | Q15: =IFERROR(IF(INDEX('PROJETO PERFURAÇÃO'!$P:$P,MATCH(MEDIÇÃO!R15,'PROJETO PERFURAÇÃO'!$B:$B,0))="Production","P",IF(INDEX('PROJETO PERFURAÇÃO'!$P:$P,MATCH(MEDIÇÃO!R15,'PROJETO PERFURAÇÃO'!$B:$B,0))="Buffer","B",IF(INDEX('PROJETO PERFURAÇÃO'!$P:$P,MATCH(MEDIÇÃO!R15,'PROJETO PERFURAÇÃO'!$B:$B,0))="Pre-Splitting","S"))),"") -> S | R15: =R14+1 -> 57 | S15: =IFERROR(INDEX('LEV R&D'!$D:$D,MATCH(MEDIÇÃO!R15,'LEV R&D'!$A:$A,0))-INDEX('PROJETO PERFURAÇÃO'!$AH:$AH,MATCH(MEDIÇÃO!R15,'PROJETO PERFURAÇÃO'!$B:$B,0)),"") | T15: =IFERROR(INDEX('PROJETO PERFURAÇÃO'!$AN:$AN,MATCH(MEDIÇÃO!R15,'PROJETO PERFURAÇÃO'!$B:$B,0)),"") -> 14.61
B16: =IFERROR(ROUND(INDEX('PROJETO PERFURAÇÃO'!$AB:$AB,MATCH(MEDIÇÃO!D16,'PROJETO PERFURAÇÃO'!$B:$B,0)),1)&"''","") -> 5'' | C16: =IFERROR(IF(INDEX('PROJETO PERFURAÇÃO'!$P:$P,MATCH(MEDIÇÃO!D16,'PROJETO PERFURAÇÃO'!$B:$B,0))="Production","P",IF(INDEX('PROJETO PERFURAÇÃO'!$P:$P,MATCH(MEDIÇÃO!D16,'PROJETO PERFURAÇÃO'!$B:$B,0))="Buffer","B",IF(INDEX('PROJETO PERFURAÇÃO'!$P:$P,MATCH(MEDIÇÃO!D16,'PROJETO PERFURAÇÃO'!$B:$B,0))="Pre-Splitting","S"))),"") -> S | D16: =D15+1 -> 12 | E16: =IFERROR(INDEX('LEV R&D'!$D:$D,MATCH(MEDIÇÃO!D16,'LEV R&D'!$A:$A,0))-INDEX('PROJETO PERFURAÇÃO'!$AH:$AH,MATCH(MEDIÇÃO!D16,'PROJETO PERFURAÇÃO'!$B:$B,0)),"") | F16: =IFERROR(INDEX('PROJETO PERFURAÇÃO'!$AN:$AN,MATCH(MEDIÇÃO!D16,'PROJETO PERFURAÇÃO'!$B:$B,0)),"") -> 14.78 | I16: =IFERROR(ROUND(INDEX('PROJETO PERFURAÇÃO'!$AB:$AB,MATCH(MEDIÇÃO!K16,'PROJETO PERFURAÇÃO'!$B:$B,0)),1)&"''","") -> 5'' | J16: =IFERROR(IF(INDEX('PROJETO PERFURAÇÃO'!$P:$P,MATCH(MEDIÇÃO!K16,'PROJETO PERFURAÇÃO'!$B:$B,0))="Production","P",IF(INDEX('PROJETO PERFURAÇÃO'!$P:$P,MATCH(MEDIÇÃO!K16,'PROJETO PERFURAÇÃO'!$B:$B,0))="Buffer","B",IF(INDEX('PROJETO PERFURAÇÃO'!$P:$P,MATCH(MEDIÇÃO!K16,'PROJETO PERFURAÇÃO'!$B:$B,0))="Pre-Splitting","S"))),"") -> S | K16: =K15+1 -> 35 | L16: =IFERROR(INDEX('LEV R&D'!$D:$D,MATCH(MEDIÇÃO!K16,'LEV R&D'!$A:$A,0))-INDEX('PROJETO PERFURAÇÃO'!$AH:$AH,MATCH(MEDIÇÃO!K16,'PROJETO PERFURAÇÃO'!$B:$B,0)),"") | M16: =IFERROR(INDEX('PROJETO PERFURAÇÃO'!$AN:$AN,MATCH(MEDIÇÃO!K16,'PROJETO PERFURAÇÃO'!$B:$B,0)),"") -> 14.42 | P16: =IFERROR(ROUND(INDEX('PROJETO PERFURAÇÃO'!$AB:$AB,MATCH(MEDIÇÃO!R16,'PROJETO PERFURAÇÃO'!$B:$B,0)),1)&"''","") -> 5'' | Q16: =IFERROR(IF(INDEX('PROJETO PERFURAÇÃO'!$P:$P,MATCH(MEDIÇÃO!R16,'PROJETO PERFURAÇÃO'!$B:$B,0))="Production","P",IF(INDEX('PROJETO PERFURAÇÃO'!$P:$P,MATCH(MEDIÇÃO!R16,'PROJETO PERFURAÇÃO'!$B:$B,0))="Buffer","B",IF(INDEX('PROJETO PERFURAÇÃO'!$P:$P,MATCH(MEDIÇÃO!R16,'PROJETO PERFURAÇÃO'!$B:$B,0))="Pre-Splitting","S"))),"") -> S | R16: =R15+1 -> 58 | S16: =IFERROR(INDEX('LEV R&D'!$D:$D,MATCH(MEDIÇÃO!R16,'LEV R&D'!$A:$A,0))-INDEX('PROJETO PERFURAÇÃO'!$AH:$AH,MATCH(MEDIÇÃO!R16,'PROJETO PERFURAÇÃO'!$B:$B,0)),"") | T16: =IFERROR(INDEX('PROJETO PERFURAÇÃO'!$AN:$AN,MATCH(MEDIÇÃO!R16,'PROJETO PERFURAÇÃO'!$B:$B,0)),"") -> 14.7
B17: =IFERROR(ROUND(INDEX('PROJETO PERFURAÇÃO'!$AB:$AB,MATCH(MEDIÇÃO!D17,'PROJETO PERFURAÇÃO'!$B:$B,0)),1)&"''","") -> 5'' | C17: =IFERROR(IF(INDEX('PROJETO PERFURAÇÃO'!$P:$P,MATCH(MEDIÇÃO!D17,'PROJETO PERFURAÇÃO'!$B:$B,0))="Production","P",IF(INDEX('PROJETO PERFURAÇÃO'!$P:$P,MATCH(MEDIÇÃO!D17,'PROJETO PERFURAÇÃO'!$B:$B,0))="Buffer","B",IF(INDEX('PROJETO PERFURAÇÃO'!$P:$P,MATCH(MEDIÇÃO!D17,'PROJETO PERFURAÇÃO'!$B:$B,0))="Pre-Splitting","S"))),"") -> S | D17: =D16+1 -> 13 | E17: =IFERROR(INDEX('LEV R&D'!$D:$D,MATCH(MEDIÇÃO!D17,'LEV R&D'!$A:$A,0))-INDEX('PROJETO PERFURAÇÃO'!$AH:$AH,MATCH(MEDIÇÃO!D17,'PROJETO PERFURAÇÃO'!$B:$B,0)),"") | F17: =IFERROR(INDEX('PROJETO PERFURAÇÃO'!$AN:$AN,MATCH(MEDIÇÃO!D17,'PROJETO PERFURAÇÃO'!$B:$B,0)),"") -> 14.88 | I17: =IFERROR(ROUND(INDEX('PROJETO PERFURAÇÃO'!$AB:$AB,MATCH(MEDIÇÃO!K17,'PROJETO PERFURAÇÃO'!$B:$B,0)),1)&"''","") -> 5'' | J17: =IFERROR(IF(INDEX('PROJETO PERFURAÇÃO'!$P:$P,MATCH(MEDIÇÃO!K17,'PROJETO PERFURAÇÃO'!$B:$B,0))="Production","P",IF(INDEX('PROJETO PERFURAÇÃO'!$P:$P,MATCH(MEDIÇÃO!K17,'PROJETO PERFURAÇÃO'!$B:$B,0))="Buffer","B",IF(INDEX('PROJETO PERFURAÇÃO'!$P:$P,MATCH(MEDIÇÃO!K17,'PROJETO PERFURAÇÃO'!$B:$B,0))="Pre-Splitting","S"))),"") -> S | K17: =K16+1 -> 36 | L17: =IFERROR(INDEX('LEV R&D'!$D:$D,MATCH(MEDIÇÃO!K17,'LEV R&D'!$A:$A,0))-INDEX('PROJETO PERFURAÇÃO'!$AH:$AH,MATCH(MEDIÇÃO!K17,'PROJETO PERFURAÇÃO'!$B:$B,0)),"") | M17: =IFERROR(INDEX('PROJETO PERFURAÇÃO'!$AN:$AN,MATCH(MEDIÇÃO!K17,'PROJETO PERFURAÇÃO'!$B:$B,0)),"") -> 14.54 | P17: =IFERROR(ROUND(INDEX('PROJETO PERFURAÇÃO'!$AB:$AB,MATCH(MEDIÇÃO!R17,'PROJETO PERFURAÇÃO'!$B:$B,0)),1)&"''","") -> 5'' | Q17: =IFERROR(IF(INDEX('PROJETO PERFURAÇÃO'!$P:$P,MATCH(MEDIÇÃO!R17,'PROJETO PERFURAÇÃO'!$B:$B,0))="Production","P",IF(INDEX('PROJETO PERFURAÇÃO'!$P:$P,MATCH(MEDIÇÃO!R17,'PROJETO PERFURAÇÃO'!$B:$B,0))="Buffer","B",IF(INDEX('PROJETO PERFURAÇÃO'!$P:$P,MATCH(MEDIÇÃO!R17,'PROJETO PERFURAÇÃO'!$B:$B,0))="Pre-Splitting","S"))),"") -> S | R17: =R16+1 -> 59 | S17: =IFERROR(INDEX('LEV R&D'!$D:$D,MATCH(MEDIÇÃO!R17,'LEV R&D'!$A:$A,0))-INDEX('PROJETO PERFURAÇÃO'!$AH:$AH,MATCH(MEDIÇÃO!R17,'PROJETO PERFURAÇÃO'!$B:$B,0)),"") | T17: =IFERROR(INDEX('PROJETO PERFURAÇÃO'!$AN:$AN,MATCH(MEDIÇÃO!R17,'PROJETO PERFURAÇÃO'!$B:$B,0)),"") -> 14.77
... B27: =IFERROR(ROUND(INDEX('PROJETO PERFURAÇÃO'!$AB:$AB,MATCH(MEDIÇÃO!D27,'PROJETO PERFURAÇÃO'!$B:$B,0)),1)&"''","") -> 5'' | C27: =IFERROR(IF(INDEX('PROJETO PERFURAÇÃO'!$P:$P,MATCH(MEDIÇÃO!D27,'PROJETO PERFURAÇÃO'!$B:$B,0))="Production","P",IF(INDEX('PROJETO PERFURAÇÃO'!$P:$P,MATCH(MEDIÇÃO!D27,'PROJETO PERFURAÇÃO'!$B:$B,0))="Buffer","B",IF(INDEX('PROJETO PERFURAÇÃO'!$P:$P,MATCH(MEDIÇÃO!D27,'PROJETO PERFURAÇÃO'!$B:$B,0))="Pre-Splitting","S"))),"") -> S | D27: =D26+1 -> 23 | E27: =IFERROR(INDEX('LEV R&D'!$D:$D,MATCH(MEDIÇÃO!D27,'LEV R&D'!$A:$A,0))-INDEX('PROJETO PERFURAÇÃO'!$AH:$AH,MATCH(MEDIÇÃO!D27,'PROJETO PERFURAÇÃO'!$B:$B,0)),"") | F27: =IFERROR(INDEX('PROJETO PERFURAÇÃO'!$AN:$AN,MATCH(MEDIÇÃO!D27,'PROJETO PERFURAÇÃO'!$B:$B,0)),"") -> 13.75 | I27: =IFERROR(ROUND(INDEX('PROJETO PERFURAÇÃO'!$AB:$AB,MATCH(MEDIÇÃO!K27,'PROJETO PERFURAÇÃO'!$B:$B,0)),1)&"''","") -> 5'' | J27: =IFERROR(IF(INDEX('PROJETO PERFURAÇÃO'!$P:$P,MATCH(MEDIÇÃO!K27,'PROJETO PERFURAÇÃO'!$B:$B,0))="Production","P",IF(INDEX('PROJETO PERFURAÇÃO'!$P:$P,MATCH(MEDIÇÃO!K27,'PROJETO PERFURAÇÃO'!$B:$B,0))="Buffer","B",IF(INDEX('PROJETO PERFURAÇÃO'!$P:$P,MATCH(MEDIÇÃO!K27,'PROJETO PERFURAÇÃO'!$B:$B,0))="Pre-Splitting","S"))),"") -> S | K27: =K26+1 -> 46 | L27: =IFERROR(INDEX('LEV R&D'!$D:$D,MATCH(MEDIÇÃO!K27,'LEV R&D'!$A:$A,0))-INDEX('PROJETO PERFURAÇÃO'!$AH:$AH,MATCH(MEDIÇÃO!K27,'PROJETO PERFURAÇÃO'!$B:$B,0)),"") | M27: =IFERROR(INDEX('PROJETO PERFURAÇÃO'!$AN:$AN,MATCH(MEDIÇÃO!K27,'PROJETO PERFURAÇÃO'!$B:$B,0)),"") -> 14.67 | P27: =IFERROR(ROUND(INDEX('PROJETO PERFURAÇÃO'!$AB:$AB,MATCH(MEDIÇÃO!R27,'PROJETO PERFURAÇÃO'!$B:$B,0)),1)&"''","") -> 5'' | Q27: =IFERROR(IF(INDEX('PROJETO PERFURAÇÃO'!$P:$P,MATCH(MEDIÇÃO!R27,'PROJETO PERFURAÇÃO'!$B:$B,0))="Production","P",IF(INDEX('PROJETO PERFURAÇÃO'!$P:$P,MATCH(MEDIÇÃO!R27,'PROJETO PERFURAÇÃO'!$B:$B,0))="Buffer","B",IF(INDEX('PROJETO PERFURAÇÃO'!$P:$P,MATCH(MEDIÇÃO!R27,'PROJETO PERFURAÇÃO'!$B:$B,0))="Pre-Splitting","S"))),"") -> S | R27: =R26+1 -> 69 | S27: =IFERROR(INDEX('LEV R&D'!$D:$D,MATCH(MEDIÇÃO!R27,'LEV R&D'!$A:$A,0))-INDEX('PROJETO PERFURAÇÃO'!$AH:$AH,MATCH(MEDIÇÃO!R27,'PROJETO PERFURAÇÃO'!$B:$B,0)),"") | T27: =IFERROR(INDEX('PROJETO PERFURAÇÃO'!$AN:$AN,MATCH(MEDIÇÃO!R27,'PROJETO PERFURAÇÃO'!$B:$B,0)),"") -> 14.92
C30: Responsável | M30: Responsável
B32: ='PROJETO PERFURAÇÃO'!$C$2&" - "&'PROJETO PERFURAÇÃO'!$H$2 -> LIB065 - PP0651026 | I32: P | J32: =Produção
I33: B | J33: =Buffer
I34: S | J34: =Pré Corte
B35: Ø | C35: Type | D35: ID | E35: Obj | F35: Inc | G35: Perf | H35: Rep | I35: Ø | J35: Type | K35: ID | L35: Obj | M35: Inc | N35: Perf | O35: Rep | P35: Ø | Q35: Type | R35: ID | S35: Obj | T35: Inc | U35: Perf | V35: Rep
